Workbook

Sheet Profit Loss-Combined
A1: Technocraft Fashions Limited
A3: Combined Profit & Loss for the Period ended Feb,2026
BD4: Amount in ₹
B5: Amount in ₹ | C5: For April,2025 | G5: Upto May,2025 | J5: Upto May,2025 | K5: For May,2025 | L5: Amravati | M5: Betul | N5: Interunit | O5: Upto June,2025 | P5: For June,2025 | Q5: Amravati | R5: Betul | S5: Interunit | T5: Upto July,2025 | U5: For July,2025 | V5: Amravati | W5: Betul | X5: Interunit | Y5: Upto Aug,2025 | Z5: For Aug,2025 | AA5: Amravati | AB5: Betul | AC5: Interunit | AD5: Upto Sept,2025 | AE5: For Sept,2025 | AF5: Amravati | AG5: Betul | AH5: Interunit | AI5: Upto Oct,2025 | AJ5: For Oct,2025 | AK5: Amravati | AL5: Betul | AM5: Interunit | AN5: Upto Nov ,2025 | AO5: For Nov,2025 | AP5: Amravati | AQ5: Betul | AR5: Interunit | AS5: Upto Dec ,2025 | AT5: For Dec,2025 | AU5: Amravati | AV5: Betul | AW5: Interunit | AX5: Upto Jan ,2026 | AY5: For Jan,2026 | AZ5: Amravati | BA5: Betul | BB5: Interunit | BC5: Upto Feb ,2026 | BD5: For Feb,2026
A6: PARTICULARS | B6: April,2025-Textile | C6: Amravati | D6: Betul | E6: Inter Unit | G6: Amravati | H6: Betul | I6: Inter Unit
A7: INCOME
A8: SALES
A9: SALE LOCAL - MISCELLANEOUS ITEMS | C9: =VLOOKUP(A9,'Profit Loss-Amravati-25-26'!$A$13:$B$190,2,0) -> 21860 | F9: =+B9+C9+D9 -> 21860 | G9: =VLOOKUP(A9,'Profit Loss-Amravati-25-26'!$A$9:$D$190,3,0) -> 21860 | J9: =SUM(G9:I9) -> 21860 | K9: =+H9+G9-F9 -> 0 | L9: =VLOOKUP(A9,'Profit Loss-Amravati-25-26'!$A$9:$F$190,5,0) -> 21860 | O9: =+L9+M9 -> 21860 | P9: =+O9-J9 -> 0 | Q9: =VLOOKUP(A9,'Profit Loss-Amravati-25-26'!$A$9:$H$190,7,0) -> 21860 | T9: =+Q9+R9 -> 21860 | U9: =+T9-O9 -> 0 | V9: =VLOOKUP(A9,'Profit Loss-Amravati-25-26'!$A$9:$J$190,9,0) -> 21860 | Y9: =+V9+W9 -> 21860 | Z9: =+Y9-T9 -> 0 | AA9: =VLOOKUP(A9,'Profit Loss-Amravati-25-26'!$A$9:$L$192,11,0) -> 21860 | AD9: =+AA9+AB9-AC9 -> 21860 | AE9: =+AD9-Y9 -> 0 | AF9: =VLOOKUP(A9,'Profit Loss-Amravati-25-26'!$A$9:$N$192,13,0) -> 21860 | AI9: =+AF9+AG9-AH9 -> 21860 | AJ9: =+AI9-AD9 -> 0 | AK9: =VLOOKUP(A9,'Profit Loss-Amravati-25-26'!$A$9:$P$192,15,0) -> 21860 | AN9: =+AK9+AL9-AM9 -> 21860 | AO9: =+AN9-AI9 -> 0 | AP9: =VLOOKUP(A9,'Profit Loss-Amravati-25-26'!$A$9:$R$192,17,0) -> 21860 | AS9: =+AP9+AQ9-AR9 -> 21860 | AT9: =+AS9-AN9 -> 0 | AU9: =VLOOKUP(A9,'Profit Loss-Amravati-25-26'!$A$9:$T$192,19,0) -> 21860 | AX9: =+AU9+AV9-AW9 -> 21860 | AY9: =+AX9-AS9 -> 0 | AZ9: =VLOOKUP(A9,'Profit Loss-Amravati-25-26'!$A$9:$V$192,21,0) -> 21860 | BC9: =+AZ9+BA9-BB9 -> 21860 | BD9: =+BC9-AX9 -> 0
A10: SALE LOCAL (GARMENT) | C10: =VLOOKUP(A10,'Profit Loss-Amravati-25-26'!$A$13:$B$190,2,0) -> 47838869 | F10: =+B10+C10+D10 -> 47838869 | G10: =VLOOKUP(A10,'Profit Loss-Amravati-25-26'!$A$9:$D$190,3,0) -> 93255699 | J10: =SUM(G10:I10) -> 93255699 | K10: =+H10+G10-F10 -> 45416830 | L10: =VLOOKUP(A10,'Profit Loss-Amravati-25-26'!$A$9:$F$190,5,0) -> 1.4859851e+08 | O10: =+L10+M10 -> 1.4859851e+08 | P10: =+O10-J10 -> 55342806 | Q10: =VLOOKUP(A10,'Profit Loss-Amravati-25-26'!$A$9:$H$190,7,0) -> 2.2662015e+08 | T10: =+Q10+R10 -> 2.2662015e+08 | U10: =+T10-O10 -> 78021644 | V10: =VLOOKUP(A10,'Profit Loss-Amravati-25-26'!$A$9:$J$190,9,0) -> 2.7676371e+08 | Y10: =+V10+W10 -> 2.7676371e+08 | Z10: =+Y10-T10 -> 50143556 | AA10: =VLOOKUP(A10,'Profit Loss-Amravati-25-26'!$A$9:$L$192,11,0) -> 3.6038358e+08 | AD10: =+AA10+AB10-AC10 -> 3.6038358e+08 | AE10: =+AD10-Y10 -> 83619871 | AF10: =VLOOKUP(A10,'Profit Loss-Amravati-25-26'!$A$9:$N$192,13,0) -> 3.919506e+08 | AI10: =+AF10+AG10-AH10 -> 3.919506e+08 | AJ10: =+AI10-AD10 -> 31567025 | AK10: =VLOOKUP(A10,'Profit Loss-Amravati-25-26'!$A$9:$P$192,15,0) -> 4.3805378e+08 | AN10: =+AK10+AL10-AM10 -> 4.3805378e+08 | AO10: =+AN10-AI10 -> 46103174 | AP10: =VLOOKUP(A10,'Profit Loss-Amravati-25-26'!$A$9:$R$192,17,0) -> 5.1824433e+08 | AS10: =+AP10+AQ10-AR10 -> 5.1824433e+08 | AT10: =+AS10-AN10 -> 80190553 | AU10: =VLOOKUP(A10,'Profit Loss-Amravati-25-26'!$A$9:$T$192,19,0) -> 5.9101041e+08 | AX10: =+AU10+AV10-AW10 -> 5.9101041e+08 | AY10: =+AX10-AS10 -> 72766078 | AZ10: =VLOOKUP(A10,'Profit Loss-Amravati-25-26'!$A$9:$V$192,21,0) -> 6.4868176e+08 | BC10: =+AZ10+BA10-BB10 -> 6.4868176e+08 | BD10: =+BC10-AX10 -> 57671352
A11: SALE EXPORT - FABRIC- (SAMPLE) | AU11: =VLOOKUP(A11,'Profit Loss-Amravati-25-26'!$A$9:$T$192,19,0) -> 0 | AX11: =+AU11+AV11-AW11 -> 0 | AY11: =+AX11-AS11 -> 0 | AZ11: =VLOOKUP(A11,'Profit Loss-Amravati-25-26'!$A$9:$V$192,21,0) -> 0 | BC11: =+AZ11+BA11-BB11 -> 0 | BD11: =+BC11-AX11 -> 0
A12: SAMPLE DEVELOPMENT SERVICES | AU12: =VLOOKUP(A12,'Profit Loss-Amravati-25-26'!$A$9:$T$192,19,0) -> 646961 | AX12: =+AU12+AV12-AW12 -> 646961 | AY12: =+AX12-AS12 -> 646961 | AZ12: =VLOOKUP(A12,'Profit Loss-Amravati-25-26'!$A$9:$V$192,21,0) -> 646961 | BC12: =+AZ12+BA12-BB12 -> 646961 | BD12: =+BC12-AX12 -> 0
A13: SALE LOCAL | C13: =VLOOKUP(A13,'Profit Loss-Amravati-25-26'!$A$13:$B$190,2,0) -> 26900 | F13: =+B13+C13+D13 -> 26900 | G13: =VLOOKUP(A13,'Profit Loss-Amravati-25-26'!$A$9:$D$190,3,0) -> 162790 | J13: =SUM(G13:I13) -> 162790 | K13: =+H13+G13-F13 -> 135890 | L13: =VLOOKUP(A13,'Profit Loss-Amravati-25-26'!$A$9:$F$190,5,0) -> 162790 | O13: =+L13+M13 -> 162790 | P13: =+O13-J13 -> 0 | Q13: =VLOOKUP(A13,'Profit Loss-Amravati-25-26'!$A$9:$H$190,7,0) -> 185950 | T13: =+Q13+R13 -> 185950 | U13: =+T13-O13 -> 23160 | V13: =VLOOKUP(A13,'Profit Loss-Amravati-25-26'!$A$9:$J$190,9,0) -> 205290 | Y13: =+V13+W13 -> 205290 | Z13: =+Y13-T13 -> 19340 | AA13: =VLOOKUP(A13,'Profit Loss-Amravati-25-26'!$A$9:$L$192,11,0) -> 439540 | AD13: =+AA13+AB13-AC13 -> 439540 | AE13: =+AD13-Y13 -> 234250 | AF13: =VLOOKUP(A13,'Profit Loss-Amravati-25-26'!$A$9:$N$192,13,0) -> 471500 | AI13: =+AF13+AG13-AH13 -> 471500 | AJ13: =+AI13-AD13 -> 31960 | AK13: =VLOOKUP(A13,'Profit Loss-Amravati-25-26'!$A$9:$P$192,15,0) -> 471500.01 | AN13: =+AK13+AL13-AM13 -> 471500.01 | AO13: =+AN13-AI13 -> 0.01 | AP13: =VLOOKUP(A13,'Profit Loss-Amravati-25-26'!$A$9:$R$192,17,0) -> 471500.01 | AS13: =+AP13+AQ13-AR13 -> 471500.01 | AT13: =+AS13-AN13 -> 0 | AU13: =VLOOKUP(A13,'Profit Loss-Amravati-25-26'!$A$9:$T$192,19,0) -> 471500.01 | AX13: =+AU13+AV13-AW13 -> 471500.01 | AY13: =+AX13-AS13 -> 0 | AZ13: =VLOOKUP(A13,'Profit Loss-Amravati-25-26'!$A$9:$V$192,21,0) -> 471500.01 | BC13: =+AZ13+BA13-BB13 -> 471500.01 | BD13: =+BC13-AX13 -> 0
A14: SALE EXPORT FABRIC | AK14: =VLOOKUP(A14,'Profit Loss-Amravati-25-26'!$A$9:$P$192,15,0) -> 72061522 | AN14: =+AK14+AL14-AM14 -> 72061522 | AO14: =+AN14-AI14 -> 72061522 | AP14: =VLOOKUP(A14,'Profit Loss-Amravati-25-26'!$A$9:$R$192,17,0) -> 150117512 | AS14: =+AP14+AQ14-AR14 -> 150117512 | AT14: =+AS14-AN14 -> 78055990 | AU14: =VLOOKUP(A14,'Profit Loss-Amravati-25-26'!$A$9:$T$192,19,0) -> 150117512 | AX14: =+AU14+AV14-AW14 -> 150117512 | AY14: =+AX14-AS14 -> 0 | AZ14: =VLOOKUP(A14,'Profit Loss-Amravati-25-26'!$A$9:$V$192,21,0) -> 158852699 | BC14: =+AZ14+BA14-BB14 -> 158852699 | BD14: =+BC14-AX14 -> 8735187
A15: SALE EXPORT (GARMENT)) | F15: 0 | G15: =VLOOKUP(A15,'Profit Loss-Amravati-25-26'!$A$9:$D$190,3,0) -> 17488529 | J15: =SUM(G15:I15) -> 17488529 | K15: =+H15+G15-F15 -> 17488529 | L15: =VLOOKUP(A15,'Profit Loss-Amravati-25-26'!$A$9:$F$190,5,0) -> 17488529 | O15: =+L15+M15 -> 17488529 | P15: =+O15-J15 -> 0 | Q15: =VLOOKUP(A15,'Profit Loss-Amravati-25-26'!$A$9:$H$190,7,0) -> 28044991 | T15: =+(Q15+R15)-352327 -> 27692664 | U15: =+T15-O15 -> 10204135 | V15: =VLOOKUP(A15,'Profit Loss-Amravati-25-26'!$A$9:$J$190,9,0) -> 38932993 | Y15: =+(V15+W15)-9215036-352327 -> 29365630 | Z15: =+Y15-T15 -> 1672966 | AA15: =VLOOKUP(A15,'Profit Loss-Amravati-25-26'!$A$9:$L$192,11,0) -> 31936237 | AD15: =+AA15+AB15-AC15 -> 31936237 | AE15: =+AD15-Y15 -> 2570607 | AF15: =VLOOKUP(A15,'Profit Loss-Amravati-25-26'!$A$9:$N$192,13,0) -> 58108673 | AI15: =+AF15+AG15-AH15 -> 58108673 | AJ15: =+AI15-AD15 -> 26172436 | AK15: =VLOOKUP(A15,'Profit Loss-Amravati-25-26'!$A$9:$P$192,15,0) -> 73649850 | AN15: =+AK15+AL15-AM15 -> 73649850 | AO15: =+AN15-AI15 -> 15541177 | AP15: =VLOOKUP(A15,'Profit Loss-Amravati-25-26'!$A$9:$R$192,17,0) -> 84681620 | AS15: =+AP15+AQ15-AR15 -> 84681620 | AT15: =+AS15-AN15 -> 11031770 | AU15: =VLOOKUP(A15,'Profit Loss-Amravati-25-26'!$A$9:$T$192,19,0) -> 84702821 | AX15: =+AU15+AV15-AW15 -> 84702821 | AY15: =+AX15-AS15 -> 21201 | AZ15: =VLOOKUP(A15,'Profit Loss-Amravati-25-26'!$A$9:$V$192,21,0) -> 105750522 | BC15: =+AZ15+BA15-BB15 -> 105750522 | BD15: =+BC15-AX15 -> 21047701
A16: SALE TRADING - LOCAL - GARMENT | Q16: =VLOOKUP(A16,'Profit Loss-Amravati-25-26'!$A$9:$H$190,7,0) -> 1961392 | T16: =+Q16+R16 -> 1961392 | U16: =+T16-O16 -> 1961392 | V16: =VLOOKUP(A16,'Profit Loss-Amravati-25-26'!$A$9:$J$190,9,0) -> 2001211 | Y16: =+V16+W16 -> 2001211 | Z16: =+Y16-T16 -> 39819 | AA16: =VLOOKUP(A16,'Profit Loss-Amravati-25-26'!$A$9:$L$192,11,0) -> 2001211 | AD16: =+AA16+AB16-AC16 -> 2001211 | AE16: =+AD16-Y16 -> 0 | AF16: =VLOOKUP(A16,'Profit Loss-Amravati-25-26'!$A$9:$N$192,13,0) -> 2419148 | AI16: =+AF16+AG16-AH16 -> 2419148 | AJ16: =+AI16-AD16 -> 417937 | AK16: =VLOOKUP(A16,'Profit Loss-Amravati-25-26'!$A$9:$P$192,15,0) -> 2419148 | AN16: =+AK16+AL16-AM16 -> 2419148 | AO16: =+AN16-AI16 -> 0 | AP16: =VLOOKUP(A16,'Profit Loss-Amravati-25-26'!$A$9:$R$192,17,0) -> 2821225 | AS16: =+AP16+AQ16-AR16 -> 2821225 | AT16: =+AS16-AN16 -> 402077 | AU16: =VLOOKUP(A16,'Profit Loss-Amravati-25-26'!$A$9:$T$192,19,0) -> 3094230 | AX16: =+AU16+AV16-AW16 -> 3094230 | AY16: =+AX16-AS16 -> 273005 | AZ16: =VLOOKUP(A16,'Profit Loss-Amravati-25-26'!$A$9:$V$192,21,0) -> 4971595 | BC16: =+AZ16+BA16-BB16 -> 4971595 | BD16: =+BC16-AX16 -> 1877365
A17: SALE TRADING - LOCAL - FABRIC | C17: =VLOOKUP(A17,'Profit Loss-Amravati-25-26'!$A$13:$B$190,2,0) -> 1704310 | F17: =+B17+C17+D17 -> 1704310 | G17: =VLOOKUP(A17,'Profit Loss-Amravati-25-26'!$A$9:$D$190,3,0) -> 1704310 | J17: =SUM(G17:I17) -> 1704310 | K17: =+H17+G17-F17 -> 0 | L17: =VLOOKUP(A17,'Profit Loss-Amravati-25-26'!$A$9:$F$190,5,0) -> 3480367 | O17: =+L17+M17 -> 3480367 | P17: =+O17-J17 -> 1776057 | Q17: =VLOOKUP(A17,'Profit Loss-Amravati-25-26'!$A$9:$H$190,7,0) -> 4008793 | T17: =+Q17+R17 -> 4008793 | U17: =+T17-O17 -> 528426 | V17: =VLOOKUP(A17,'Profit Loss-Amravati-25-26'!$A$9:$J$190,9,0) -> 4930093 | Y17: =+V17+W17 -> 4930093 | Z17: =+Y17-T17 -> 921300 | AA17: =VLOOKUP(A17,'Profit Loss-Amravati-25-26'!$A$9:$L$192,11,0) -> 5699323 | AD17: =+AA17+AB17-AC17 -> 5699323 | AE17: =+AD17-Y17 -> 769230 | AF17: =VLOOKUP(A17,'Profit Loss-Amravati-25-26'!$A$9:$N$192,13,0) -> 5699323 | AI17: =+AF17+AG17-AH17 -> 5699323 | AJ17: =+AI17-AD17 -> 0 | AK17: =VLOOKUP(A17,'Profit Loss-Amravati-25-26'!$A$9:$P$192,15,0) -> 6121968 | AN17: =+AK17+AL17-AM17 -> 6121968 | AO17: =+AN17-AI17 -> 422645 | AP17: =VLOOKUP(A17,'Profit Loss-Amravati-25-26'!$A$9:$R$192,17,0) -> 7995966 | AS17: =+AP17+AQ17-AR17 -> 7995966 | AT17: =+AS17-AN17 -> 1873998 | AU17: =VLOOKUP(A17,'Profit Loss-Amravati-25-26'!$A$9:$T$192,19,0) -> 9757463 | AX17: =+AU17+AV17-AW17 -> 9757463 | AY17: =+AX17-AS17 -> 1761497 | AZ17: =VLOOKUP(A17,'Profit Loss-Amravati-25-26'!$A$9:$V$192,21,0) -> 9760163 | BC17: =+AZ17+BA17-BB17 -> 9760163 | BD17: =+BC17-AX17 -> 2700
A18: SALES (LABOUR JOB) - INTER UNIT | D18: =VLOOKUP(A18,'Profit Loss-Betul-25-26'!$A$9:$B$140,2,0)*0+1501872 -> 1501872 | E18: 1501872 | F18: =+B18+C18+D18-E18 -> 0 | H18: =VLOOKUP(A18,'Profit Loss-Betul-25-26'!$A$9:$D$140,3,0) -> 2501098 | I18: =-H18 -> -2501098 | J18: =SUM(G18:I18) -> 0 | K18: =+H18+G18-F18+I18 -> 0 | M18: =VLOOKUP(A18,'Profit Loss-Betul-25-26'!$A$9:$F$141,5,0) -> 5286179 | N18: =-M18 -> -5286179 | O18: =SUM(L18:N18) -> 0 | P18: =+O18-J18 -> 0 | R18: =VLOOKUP(A18,'Profit Loss-Betul-25-26'!$A$9:$H$141,7,0) -> 9026583 | S18: =-R18 -> -9026583 | T18: =SUM(Q18:S18) -> 0 | U18: =+T18-O18 -> 0 | W18: =VLOOKUP(A18,'Profit Loss-Betul-25-26'!$A$9:$J$141,9,0) -> 12193532 | X18: =-W18 -> -12193532 | Y18: =SUM(V18:X18) -> 0 | Z18: =+Y18-T18 -> 0 | AB18: =VLOOKUP(A18,'Profit Loss-Betul-25-26'!$A$9:$L$141,11,0) -> 15382914 | AC18: =-AB18 -> -15382914 | AD18: =+AA18+AB18+AC18 -> 0 | AE18: =+AD18-Y18 -> 0 | AG18: =VLOOKUP(A18,'Profit Loss-Betul-25-26'!$A$9:$N$141,13,0) -> 16435708 | AH18: =+AG18 -> 16435708 | AI18: =+AF18+AG18-AH18 -> 0 | AJ18: =+AI18-AD18 -> 0 | AL18: =VLOOKUP(A18,'Profit Loss-Betul-25-26'!$A$9:$P$141,15,0) -> 18524580 | AM18: =+AL18 -> 18524580 | AN18: =+AK18+AL18-AM18 -> 0 | AO18: =+AN18-AI18 -> 0 | AQ18: =VLOOKUP(A18,'Profit Loss-Betul-25-26'!$A$9:$R$141,17,0) -> 21712831 | AR18: =+AQ18 -> 21712831 | AS18: =+AP18+AQ18-AR18 -> 0 | AT18: =+AS18-AN18 -> 0 | AV18: =VLOOKUP(A18,'Profit Loss-Betul-25-26'!$A$9:$T$141,19,0) -> 25000388 | AW18: =+AV18 -> 25000388 | AX18: =+AU18+AV18-AW18 -> 0 | AY18: =+AX18-AS18 -> 0 | BA18: =VLOOKUP(A18,'Profit Loss-Betul-25-26'!$A$9:$V$141,21,0) -> 27034065 | BB18: =+BA18 -> 27034065 | BC18: =+AZ18+BA18-BB18 -> 0 | BD18: =+BC18-AX18 -> 0
A19: GROSS SALES | B19: =SUM(B9:B18) -> 0 | C19: =SUM(C9:C18) -> 49591939 | D19: =SUM(D9:D18) -> 1501872 | F19: =SUM(F9:F18) -> 49591939 | G19: =SUM(G9:G18) -> 112633188 | H19: =SUM(H9:H18) -> 2501098 | I19: =SUM(I9:I18) -> -2501098 | J19: =SUM(J9:J18) -> 112633188 | K19: =SUM(K9:K18) -> 63041249 | L19: =SUM(L9:L18) -> 1.6975205e+08 | M19: =SUM(M9:M18) -> 5286179 | ... BD19: =SUM(BD9:BD18) -> 89334305 | BE19: =+BC19-AX19-BD19 -> 0
A20: EXPENSES RELATED TO SALES | L20: =VLOOKUP(A20,'Profit Loss-Amravati-25-26'!$A$9:$F$190,5,0) -> 0 | M20: =VLOOKUP(A20,'Profit Loss-Betul-25-26'!$A$9:$F$141,5,0) -> 0 | Q20: =VLOOKUP(A20,'Profit Loss-Amravati-25-26'!$A$9:$H$190,7,0) -> 0 | R20: =VLOOKUP(A20,'Profit Loss-Betul-25-26'!$A$9:$H$141,7,0) -> 0
A21: DELIVERY CHARGES ON SALE -GARMENT | C21: =VLOOKUP(A21,'Profit Loss-Amravati-25-26'!$A$13:$B$190,2,0) -> 212973.3 | F21: =+B21+C21+D21 -> 212973.3 | G21: =VLOOKUP(A21,'Profit Loss-Amravati-25-26'!$A$9:$D$190,3,0) -> 382533.84 | J21: =SUM(G21:I21) -> 382533.84 | K21: =+H21+G21-F21 -> 169560.54 | L21: =VLOOKUP(A21,'Profit Loss-Amravati-25-26'!$A$9:$F$190,5,0) -> 1381133.8 | O21: =SUM(L21:M21)-79796 -> 1301337.8 | P21: =+O21-J21 -> 918804 | Q21: =VLOOKUP(A21,'Profit Loss-Amravati-25-26'!$A$9:$H$190,7,0) -> 1717980.4 | T21: =+Q21+R21 -> 1717980.4 | U21: =+T21-O21 -> 416642.6 | V21: =VLOOKUP(A21,'Profit Loss-Amravati-25-26'!$A$9:$J$190,9,0) -> 1717980.4 | Y21: =+V21+W21+300000 -> 2017980.4 | Z21: =+Y21-T21 -> 300000 | AA21: =VLOOKUP(A21,'Profit Loss-Amravati-25-26'!$A$9:$L$192,11,0) -> 2180159.7 | AD21: =+AA21+AB21-AC21 -> 2180159.7 | AE21: =+AD21-Y21 -> 162179.23 | AF21: =VLOOKUP(A21,'Profit Loss-Amravati-25-26'!$A$9:$N$192,13,0) -> 2862982.8 | AG21: =VLOOKUP(A21,'Profit Loss-Betul-25-26'!$A$9:$N$141,13,0) -> 18000 | AI21: =+AF21+AG21-AH21 -> 2880982.8 | AJ21: =+AI21-AD21 -> 700823.14 | AK21: =VLOOKUP(A21,'Profit Loss-Amravati-25-26'!$A$9:$P$192,15,0) -> 3241559.8 | AL21: =VLOOKUP(A21,'Profit Loss-Betul-25-26'!$A$9:$P$141,15,0) -> 6000 | AN21: =+AK21+AL21-AM21 -> 3247559.8 | AO21: =+AN21-AI21 -> 366577.02 | AP21: =VLOOKUP(A21,'Profit Loss-Amravati-25-26'!$A$9:$R$192,17,0) -> 3456402.8 | AQ21: =VLOOKUP(A21,'Profit Loss-Betul-25-26'!$A$9:$R$141,17,0) -> 6000 | AS21: =+AP21+AQ21-AR21 -> 3462402.8 | AT21: =+AS21-AN21 -> 214843 | AU21: =VLOOKUP(A21,'Profit Loss-Amravati-25-26'!$A$9:$T$192,19,0) -> 3906763.1 | AV21: =VLOOKUP(A21,'Profit Loss-Betul-25-26'!$A$9:$T$141,19,0) -> 6000 | AX21: =+AU21+AV21-AW21 -> 3912763.1 | AY21: =+AX21-AS21 -> 450360.24 | AZ21: =VLOOKUP(A21,'Profit Loss-Amravati-25-26'!$A$9:$V$192,21,0) -> 4065545.8 | BA21: =VLOOKUP(A21,'Profit Loss-Betul-25-26'!$A$9:$V$141,21,0) -> 6000 | BC21: =+AZ21+BA21-BB21 -> 4071545.8 | BD21: =+BC21-AX21 -> 158782.69
A22: DELIVERY CHARGES ON SALES | C22: =VLOOKUP(A22,'Profit Loss-Amravati-25-26'!$A$13:$B$190,2,0) -> 15803 | F22: =+B22+C22+D22 -> 15803 | G22: =VLOOKUP(A22,'Profit Loss-Amravati-25-26'!$A$9:$D$190,3,0) -> 304524.24 | J22: =SUM(G22:I22) -> 304524.24 | K22: =+H22+G22-F22 -> 288721.24 | L22: =VLOOKUP(A22,'Profit Loss-Amravati-25-26'!$A$9:$F$190,5,0) -> 486121.24 | M22: =VLOOKUP(A22,'Profit Loss-Betul-25-26'!$A$9:$F$141,5,0) -> 12500 | O22: =SUM(L22:M22) -> 498621.24 | P22: =+O22-J22 -> 194097 | Q22: =VLOOKUP(A22,'Profit Loss-Amravati-25-26'!$A$9:$H$190,7,0)-31103 -> 2178427.2 | R22: =VLOOKUP(A22,'Profit Loss-Betul-25-26'!$A$9:$H$141,7,0) -> 12500 | T22: =+Q22+R22 -> 2190927.2 | U22: =+T22-O22 -> 1692306 | V22: =VLOOKUP(A22,'Profit Loss-Amravati-25-26'!$A$9:$J$190,9,0) -> 2668553.2 | W22: =VLOOKUP(A22,'Profit Loss-Betul-25-26'!$A$9:$J$141,9,0) -> 12500 | Y22: =+V22+W22 -> 2681053.2 | Z22: =+Y22-T22 -> 490125.98 | AA22: =VLOOKUP(A22,'Profit Loss-Amravati-25-26'!$A$9:$L$192,11,0) -> 3139356.7 | AB22: =VLOOKUP(A22,'Profit Loss-Betul-25-26'!$A$9:$L$141,11,0) -> 12500 | AD22: =+AA22+AB22-AC22 -> 3151856.7 | AE22: =+AD22-Y22 -> 470803.52 | AF22: =VLOOKUP(A22,'Profit Loss-Amravati-25-26'!$A$9:$N$192,13,0) -> 3321370.4 | AG22: =VLOOKUP(A22,'Profit Loss-Betul-25-26'!$A$9:$N$141,13,0) -> 12500 | AI22: =+AF22+AG22-AH22 -> 3333870.4 | AJ22: =+AI22-AD22 -> 182013.69 | AK22: =VLOOKUP(A22,'Profit Loss-Amravati-25-26'!$A$9:$P$192,15,0) -> 3628852.1 | AL22: =VLOOKUP(A22,'Profit Loss-Betul-25-26'!$A$9:$P$141,15,0) -> 12500 | AN22: =+AK22+AL22-AM22 -> 3641352.1 | AO22: =+AN22-AI22 -> 307481.71 | AP22: =VLOOKUP(A22,'Profit Loss-Amravati-25-26'!$A$9:$R$192,17,0) -> 4645461 | AQ22: =VLOOKUP(A22,'Profit Loss-Betul-25-26'!$A$9:$R$141,17,0) -> 12500 | AS22: =+AP22+AQ22-AR22 -> 4657961 | AT22: =+AS22-AN22 -> 1016608.9 | AU22: =VLOOKUP(A22,'Profit Loss-Amravati-25-26'!$A$9:$T$192,19,0) -> 5114840.2 | AV22: =VLOOKUP(A22,'Profit Loss-Betul-25-26'!$A$9:$T$141,19,0) -> 12500 | AX22: =+AU22+AV22-AW22 -> 5127340.2 | AY22: =+AX22-AS22 -> 469379.11 | AZ22: =VLOOKUP(A22,'Profit Loss-Amravati-25-26'!$A$9:$V$192,21,0) -> 5627752.2 | BA22: =VLOOKUP(A22,'Profit Loss-Betul-25-26'!$A$9:$V$141,21,0) -> 12500 | BC22: =+AZ22+BA22-BB22 -> 5640252.2 | BD22: =+BC22-AX22 -> 512912
A23: DOCUMENTATION CHARGES | F23: =+B23+C23+D23 -> 0 | J23: =SUM(G23:I23) -> 0 | K23: =+H23+G23-F23 -> 0 | L23: =VLOOKUP(A23,'Profit Loss-Amravati-25-26'!$A$9:$F$190,5,0) -> 0 | O23: =SUM(L23:M23) -> 0 | P23: =+O23-J23 -> 0 | Q23: =VLOOKUP(A23,'Profit Loss-Amravati-25-26'!$A$9:$H$190,7,0) -> 0 | T23: =SUM(Q23:R23) -> 0 | U23: =+T23-O23 -> 0 | V23: =VLOOKUP(A23,'Profit Loss-Amravati-25-26'!$A$9:$J$190,9,0) -> 0 | Y23: =SUM(V23:W23) -> 0 | Z23: =+Y23-T23 -> 0 | AA23: =VLOOKUP(A23,'Profit Loss-Amravati-25-26'!$A$9:$L$192,11,0) -> 0 | AD23: =+AA23+AB23-AC23 -> 0 | AE23: =+AD23-Y23 -> 0 | AF23: =VLOOKUP(A23,'Profit Loss-Amravati-25-26'!$A$9:$N$192,13,0) -> 0 | AI23: =+AF23+AG23-AH23 -> 0 | AJ23: =+AI23-AD23 -> 0 | AK23: =VLOOKUP(A23,'Profit Loss-Amravati-25-26'!$A$9:$P$192,15,0) -> 0 | AN23: =+AK23+AL23-AM23 -> 0 | AO23: =+AN23-AI23 -> 0 | AP23: =VLOOKUP(A23,'Profit Loss-Amravati-25-26'!$A$9:$R$192,17,0) -> 0 | AS23: =+AP23+AQ23-AR23 -> 0 | AT23: =+AS23-AN23 -> 0 | AU23: =VLOOKUP(A23,'Profit Loss-Amravati-25-26'!$A$9:$T$192,19,0) -> 0 | AX23: =+AU23+AV23-AW23 -> 0 | AY23: =+AX23-AS23 -> 0 | AZ23: =VLOOKUP(A23,'Profit Loss-Amravati-25-26'!$A$9:$V$192,21,0) -> 0 | BC23: =+AZ23+BA23-BB23 -> 0 | BD23: =+BC23-AX23 -> 0
A24: EXPORT EXPENSES | F24: =+B24+C24+D24 -> 0 | J24: =SUM(G24:I24) -> 0 | K24: =+H24+G24-F24 -> 0 | L24: =VLOOKUP(A24,'Profit Loss-Amravati-25-26'!$A$9:$F$190,5,0)*0 -> 0 | O24: =SUM(L24:M24) -> 0 | P24: =+O24-J24 -> 0 | Q24: =VLOOKUP(A24,'Profit Loss-Amravati-25-26'!$A$9:$H$190,7,0)-256403 -> 0.22 | T24: =SUM(Q24:R24) -> 0.22 | U24: =+T24-O24 -> 0.22 | V24: =VLOOKUP(A24,'Profit Loss-Amravati-25-26'!$A$9:$J$190,9,0)*0 -> 0 | Y24: =SUM(V24:W24) -> 0 | Z24: =+Y24-T24 -> -0.22 | AA24: =VLOOKUP(A24,'Profit Loss-Amravati-25-26'!$A$9:$L$192,11,0)-461456 -> 13498 | AD24: =+AA24+AB24-AC24-13498 -> 0 | AE24: =+AD24-Y24 -> 0 | AF24: =VLOOKUP(A24,'Profit Loss-Amravati-25-26'!$A$9:$N$192,13,0) -> 659088 | AJ24: =+AI24-AD24 -> 0 | AK24: =VLOOKUP(A24,'Profit Loss-Amravati-25-26'!$A$9:$P$192,15,0) -> 1150110.2 | AO24: =+AN24-AI24 -> 0 | AP24: =VLOOKUP(A24,'Profit Loss-Amravati-25-26'!$A$9:$R$192,17,0) -> 1796205.2 | AT24: =+AS24-AN24 -> 0 | AU24: =VLOOKUP(A24,'Profit Loss-Amravati-25-26'!$A$9:$T$192,19,0) -> 1808425 | AY24: =+AX24-AS24 -> 0 | AZ24: =VLOOKUP(A24,'Profit Loss-Amravati-25-26'!$A$9:$V$192,21,0)*0 -> 0 | BD24: =+BC24-AX24 -> 0
A25: TERMINAL HANDLING CHARGES | F25: =+B25+C25+D25 -> 0 | J25: =SUM(G25:I25) -> 0 | K25: =+H25+G25-F25 -> 0 | L25: =VLOOKUP(A25,'Profit Loss-Amravati-25-26'!$A$9:$F$190,5,0) -> 0 | O25: =SUM(L25:M25) -> 0 | P25: =+O25-J25 -> 0 | Q25: =VLOOKUP(A25,'Profit Loss-Amravati-25-26'!$A$9:$H$190,7,0) -> 0 | T25: =SUM(Q25:R25) -> 0 | U25: =+T25-O25 -> 0 | V25: =VLOOKUP(A25,'Profit Loss-Amravati-25-26'!$A$9:$J$190,9,0) -> 0 | Y25: =SUM(V25:W25) -> 0 | Z25: =+Y25-T25 -> 0 | AA25: =VLOOKUP(A25,'Profit Loss-Amravati-25-26'!$A$9:$L$192,11,0) -> 0 | AD25: =+AA25+AB25-AC25 -> 0 | AE25: =+AD25-Y25 -> 0 | AF25: =VLOOKUP(A25,'Profit Loss-Amravati-25-26'!$A$9:$N$192,13,0) -> 0 | AI25: =+AF25+AG25-AH25 -> 0 | AJ25: =+AI25-AD25 -> 0 | AK25: =VLOOKUP(A25,'Profit Loss-Amravati-25-26'!$A$9:$P$192,15,0) -> 0 | AN25: =+AK25+AL25-AM25 -> 0 | AO25: =+AN25-AI25 -> 0 | AS25: =+AP25+AQ25-AR25 -> 0 | AT25: =+AS25-AN25 -> 0 | AU25: =VLOOKUP(A25,'Profit Loss-Amravati-25-26'!$A$9:$T$192,19,0) -> 0 | AX25: =+AU25+AV25-AW25 -> 0 | AY25: =+AX25-AS25 -> 0 | AZ25: =VLOOKUP(A25,'Profit Loss-Amravati-25-26'!$A$9:$V$192,21,0) -> 0 | BC25: =+AZ25+BA25-BB25 -> 0 | BD25: =+BC25-AX25 -> 0
A26: FREIGHT ON EXPORT - (AIR) | V26: =VLOOKUP(A26,'Profit Loss-Amravati-25-26'!$A$9:$J$190,9,0) -> 0 | Y26: =SUM(V26:W26) -> 0 | Z26: =+Y26-T26 -> 0 | AA26: =VLOOKUP(A26,'Profit Loss-Amravati-25-26'!$A$9:$L$192,11,0) -> 0 | AD26: =+AA26+AB26-AC26 -> 0 | AE26: =+AD26-Y26 -> 0 | AF26: =VLOOKUP(A26,'Profit Loss-Amravati-25-26'!$A$9:$N$192,13,0) -> 0 | AI26: =+AF26+AG26-AH26 -> 0 | AJ26: =+AI26-AD26 -> 0 | AK26: =VLOOKUP(A26,'Profit Loss-Amravati-25-26'!$A$9:$P$192,15,0) -> 0 | AN26: =+AK26+AL26-AM26 -> 0 | AO26: =+AN26-AI26 -> 0 | AS26: =+AP26+AQ26-AR26 -> 0 | AT26: =+AS26-AN26 -> 0 | AU26: =VLOOKUP(A26,'Profit Loss-Amravati-25-26'!$A$9:$T$192,19,0) -> 0 | AX26: =+AU26+AV26-AW26 -> 0 | AY26: =+AX26-AS26 -> 0 | AZ26: =VLOOKUP(A26,'Profit Loss-Amravati-25-26'!$A$9:$V$192,21,0) -> 0 | BC26: =+AZ26+BA26-BB26 -> 0 | BD26: =+BC26-AX26 -> 0
A27: CLEARING CHARGES ON EXPORT | F27: =+B27+C27+D27 -> 0 | J27: =SUM(G27:I27) -> 0 | K27: =+H27+G27-F27 -> 0 | L27: =VLOOKUP(A27,'Profit Loss-Amravati-25-26'!$A$9:$F$190,5,0) -> 0 | O27: =SUM(L27:M27) -> 0 | P27: =+O27-J27 -> 0 | Q27: =VLOOKUP(A27,'Profit Loss-Amravati-25-26'!$A$9:$H$190,7,0) -> 0 | T27: =SUM(Q27:R27) -> 0 | U27: =+T27-O27 -> 0 | V27: =VLOOKUP(A27,'Profit Loss-Amravati-25-26'!$A$9:$J$190,9,0) -> 0 | Y27: =SUM(V27:W27) -> 0 | Z27: =+Y27-T27 -> 0 | AA27: =VLOOKUP(A27,'Profit Loss-Amravati-25-26'!$A$9:$L$192,11,0) -> 0 | AD27: =+AA27+AB27-AC27 -> 0 | AE27: =+AD27-Y27 -> 0 | AF27: =VLOOKUP(A27,'Profit Loss-Amravati-25-26'!$A$9:$N$192,13,0) -> 0 | AI27: =+AF27+AG27-AH27 -> 0 | AJ27: =+AI27-AD27 -> 0 | AK27: =VLOOKUP(A27,'Profit Loss-Amravati-25-26'!$A$9:$P$192,15,0) -> 0 | AN27: =+AK27+AL27-AM27 -> 0 | AO27: =+AN27-AI27 -> 0 | AS27: =+AP27+AQ27-AR27 -> 0 | AT27: =+AS27-AN27 -> 0 | AU27: =VLOOKUP(A27,'Profit Loss-Amravati-25-26'!$A$9:$T$192,19,0) -> 0 | AX27: =+AU27+AV27-AW27 -> 0 | AY27: =+AX27-AS27 -> 0 | AZ27: =VLOOKUP(A27,'Profit Loss-Amravati-25-26'!$A$9:$V$192,21,0) -> 0 | BC27: =+AZ27+BA27-BB27 -> 0 | BD27: =+BC27-AX27 -> 0
A28: DETENTION CHARGES ON EXPORT | F28: =+B28+C28+D28 -> 0 | J28: =SUM(G28:I28) -> 0 | K28: =+H28+G28-F28 -> 0 | L28: =VLOOKUP(A28,'Profit Loss-Amravati-25-26'!$A$9:$F$190,5,0) -> 0 | O28: =SUM(L28:M28) -> 0 | P28: =+O28-J28 -> 0 | Q28: =VLOOKUP(A28,'Profit Loss-Amravati-25-26'!$A$9:$H$190,7,0) -> 0 | T28: =SUM(Q28:R28) -> 0 | U28: =+T28-O28 -> 0 | V28: =VLOOKUP(A28,'Profit Loss-Amravati-25-26'!$A$9:$J$190,9,0) -> 0 | Y28: =SUM(V28:W28) -> 0 | Z28: =+Y28-T28 -> 0 | AA28: =VLOOKUP(A28,'Profit Loss-Amravati-25-26'!$A$9:$L$192,11,0) -> 0 | AD28: =+AA28+AB28-AC28 -> 0 | AE28: =+AD28-Y28 -> 0 | AF28: =VLOOKUP(A28,'Profit Loss-Amravati-25-26'!$A$9:$N$192,13,0) -> 0 | AI28: =+AF28+AG28-AH28 -> 0 | AJ28: =+AI28-AD28 -> 0 | AK28: =VLOOKUP(A28,'Profit Loss-Amravati-25-26'!$A$9:$P$192,15,0) -> 0 | AN28: =+AK28+AL28-AM28 -> 0 | AO28: =+AN28-AI28 -> 0 | AS28: =+AP28+AQ28-AR28 -> 0 | AT28: =+AS28-AN28 -> 0 | AU28: =VLOOKUP(A28,'Profit Loss-Amravati-25-26'!$A$9:$T$192,19,0) -> 0 | AX28: =+AU28+AV28-AW28 -> 0 | AY28: =+AX28-AS28 -> 0 | AZ28: =VLOOKUP(A28,'Profit Loss-Amravati-25-26'!$A$9:$V$192,21,0) -> 0 | BC28: =+AZ28+BA28-BB28 -> 0 | BD28: =+BC28-AX28 -> 0
A29: INSURANCE FOR EXPORT | F29: =+B29+C29+D29 -> 0 | J29: =SUM(G29:I29) -> 0 | K29: =+H29+G29-F29 -> 0 | O29: =SUM(L29:M29) -> 0 | P29: =+O29-J29 -> 0 | T29: =SUM(Q29:R29) -> 0 | U29: =+T29-O29 -> 0 | Y29: =SUM(V29:W29) -> 0 | Z29: =+Y29-T29 -> 0 | AD29: =+AA29+AB29-AC29 -> 0 | AE29: =+AD29-Y29 -> 0 | AI29: =+AF29+AG29-AH29 -> 0 | AJ29: =+AI29-AD29 -> 0 | AN29: =+AK29+AL29-AM29 -> 0 | AO29: =+AN29-AI29 -> 0 | AS29: =+AP29+AQ29-AR29 -> 0 | AT29: =+AS29-AN29 -> 0 | AU29: =VLOOKUP(A29,'Profit Loss-Amravati-25-26'!$A$9:$T$192,19,0) -> 0 | AX29: =+AU29+AV29-AW29 -> 0 | AY29: =+AX29-AS29 -> 0 | AZ29: =VLOOKUP(A29,'Profit Loss-Amravati-25-26'!$A$9:$V$192,21,0) -> 0 | BC29: =+AZ29+BA29-BB29 -> 0 | BD29: =+BC29-AX29 -> 0
A30: DETENTION CHARGES ON TRANSPORT | F30: =+B30+C30+D30 -> 0 | J30: =SUM(G30:I30) -> 0 | K30: =+H30+G30-F30 -> 0 | O30: =SUM(L30:M30) -> 0 | P30: =+O30-J30 -> 0 | T30: =SUM(Q30:R30) -> 0 | U30: =+T30-O30 -> 0 | Y30: =SUM(V30:W30) -> 0 | Z30: =+Y30-T30 -> 0 | AD30: =+AA30+AB30-AC30 -> 0 | AE30: =+AD30-Y30 -> 0 | AI30: =+AF30+AG30-AH30 -> 0 | AJ30: =+AI30-AD30 -> 0 | AN30: =+AK30+AL30-AM30 -> 0 | AO30: =+AN30-AI30 -> 0 | AS30: =+AP30+AQ30-AR30 -> 0 | AT30: =+AS30-AN30 -> 0 | AX30: =+AU30+AV30-AW30 -> 0 | AY30: =+AX30-AS30 -> 0 | BC30: =+AZ30+BA30-BB30 -> 0 | BD30: =+BC30-AX30 -> 0
A31: COOLIE & CARTAGE ON SALES | Y31: =SUM(V31:W31) -> 0 | Z31: =+Y31-T31 -> 0 | AA31: =VLOOKUP(A31,'Profit Loss-Amravati-25-26'!$A$9:$L$192,11,0) -> 0 | AD31: =+AA31+AB31-AC31 -> 0 | AE31: =+AD31-Y31 -> 0 | AF31: =VLOOKUP(A31,'Profit Loss-Amravati-25-26'!$A$9:$N$192,13,0) -> 0 | AI31: =+AF31+AG31-AH31 -> 0 | AJ31: =+AI31-AD31 -> 0 | AK31: =VLOOKUP(A31,'Profit Loss-Amravati-25-26'!$A$9:$P$192,15,0) -> 0 | AN31: =+AK31+AL31-AM31 -> 0 | AO31: =+AN31-AI31 -> 0 | AS31: =+AP31+AQ31-AR31 -> 0 | AT31: =+AS31-AN31 -> 0 | AU31: =VLOOKUP(A31,'Profit Loss-Amravati-25-26'!$A$9:$T$192,19,0) -> 0 | AX31: =+AU31+AV31-AW31 -> 0 | AY31: =+AX31-AS31 -> 0 | AZ31: =VLOOKUP(A31,'Profit Loss-Amravati-25-26'!$A$9:$V$192,21,0) -> 0 | BC31: =+AZ31+BA31-BB31 -> 0 | BD31: =+BC31-AX31 -> 0
A32: FREIGHT & OTHER CAHRGES ON EXPORT | F32: 0 | G32: =278950.22+8556 -> 287506.22 | J32: =278950.22+8556 -> 287506.22 | K32: =278950.22+8556 -> 287506.22 | L32: 207710 | O32: =SUM(L32:M32)+79796 -> 287506 | P32: =+O32-J32 -> -0.22 | Q32: =256403+31103 -> 287506 | T32: =SUM(Q32:R32) -> 287506 | U32: =+T32-O32 -> 0 | V32: 413637 | Y32: =SUM(V32:W32) -> 413637 | Z32: =+Y32-T32 -> 126131 | AA32: 461456 | AD32: =+AA32+AB32-AC32+13498 -> 474954 | AE32: =+AD32-Y32 -> 61317 | AI32: =+AF32+AG32-AH32+AF24 -> 659088 | AJ32: =+AI32-AD32 -> 184134 | AN32: =+AK32+AL32-AM32+AK24 -> 1150110.2 | AO32: =+AN32-AI32 -> 491022.22 | AS32: =+AP32+AQ32-AR32+AP24 -> 1796205.2 | AT32: =+AS32-AN32 -> 646095 | AX32: =+AU32+AV32-AW32+AU24 -> 1808425 | AY32: =+AX32-AS32 -> 12219.8 | AZ32: 1974917 | BC32: =+AZ32+BA32-BB32+AZ24 -> 1974917 | BD32: =+BC32-AX32 -> 166491.98
A33: PACKING EXPENSES | C33: =VLOOKUP(A33,'Profit Loss-Amravati-25-26'!$A$13:$B$190,2,0) -> 370 | F33: =+B33+C33+D33 -> 370 | G33: =VLOOKUP(A33,'Profit Loss-Amravati-25-26'!$A$9:$D$190,3,0) -> 370 | J33: =SUM(G33:I33) -> 370 | K33: =+H33+G33-F33 -> 0 | L33: =VLOOKUP(A33,'Profit Loss-Amravati-25-26'!$A$9:$F$190,5,0) -> 1170 | O33: =SUM(L33:M33) -> 1170 | P33: =+O33-J33 -> 800 | Q33: =VLOOKUP(A33,'Profit Loss-Amravati-25-26'!$A$9:$H$190,7,0) -> 1170 | T33: =+Q33+R33 -> 1170 | U33: =+T33-O33 -> 0 | V33: =VLOOKUP(A33,'Profit Loss-Amravati-25-26'!$A$9:$J$190,9,0) -> 1170 | Y33: =+V33+W33 -> 1170 | Z33: =+Y33-T33 -> 0 | AA33: =VLOOKUP(A33,'Profit Loss-Amravati-25-26'!$A$9:$L$192,11,0) -> 1170 | AD33: =+AA33+AB33-AC33 -> 1170 | AE33: =+AD33-Y33 -> 0 | AF33: =VLOOKUP(A33,'Profit Loss-Amravati-25-26'!$A$9:$N$192,13,0) -> 2270 | AI33: =+AF33+AG33-AH33 -> 2270 | AJ33: =+AI33-AD33 -> 1100 | AK33: =VLOOKUP(A33,'Profit Loss-Amravati-25-26'!$A$9:$P$192,15,0) -> 2470 | AN33: =+AK33+AL33-AM33 -> 2470 | AO33: =+AN33-AI33 -> 200 | AP33: =VLOOKUP(A33,'Profit Loss-Amravati-25-26'!$A$9:$R$192,17,0) -> 3275 | AS33: =+AP33+AQ33-AR33 -> 3275 | AT33: =+AS33-AN33 -> 805 | AU33: =VLOOKUP(A33,'Profit Loss-Amravati-25-26'!$A$9:$T$192,19,0) -> 3275 | AX33: =+AU33+AV33-AW33 -> 3275 | AY33: =+AX33-AS33 -> 0 | AZ33: =VLOOKUP(A33,'Profit Loss-Amravati-25-26'!$A$9:$V$192,21,0) -> 3275 | BC33: =+AZ33+BA33-BB33 -> 3275 | BD33: =+BC33-AX33 -> 0
A34: MARKETING DEVELOPMENT ASSISTANCE | AA34: =VLOOKUP(A34,'Profit Loss-Amravati-25-26'!$A$9:$L$192,11,0) -> 88549 | AD34: =+AA34+AB34-AC34 -> 88549 | AE34: =+AD34-Y34 -> 88549 | AF34: =VLOOKUP(A34,'Profit Loss-Amravati-25-26'!$A$9:$N$192,13,0) -> 88549 | AI34: =+AF34+AG34-AH34 -> 88549 | AJ34: =+AI34-AD34 -> 0 | AK34: =VLOOKUP(A34,'Profit Loss-Amravati-25-26'!$A$9:$P$192,15,0) -> 88549 | AN34: =+AK34+AL34-AM34 -> 88549 | AO34: =+AN34-AI34 -> 0 | AP34: =VLOOKUP(A34,'Profit Loss-Amravati-25-26'!$A$9:$R$192,17,0) -> 88549 | AS34: =+AP34+AQ34-AR34 -> 88549 | AT34: =+AS34-AN34 -> 0 | AU34: =VLOOKUP(A34,'Profit Loss-Amravati-25-26'!$A$9:$T$192,19,0) -> 88549 | AX34: =+AU34+AV34-AW34 -> 88549 | AY34: =+AX34-AS34 -> 0 | AZ34: =VLOOKUP(A34,'Profit Loss-Amravati-25-26'!$A$9:$V$192,21,0) -> 88549 | BC34: =+AZ34+BA34-BB34 -> 88549 | BD34: =+BC34-AX34 -> 0
A35: BUSINESS SUPPORT SERVICES | F35: =+B35+C35+D35 -> 0 | G35: =VLOOKUP(A35,'Profit Loss-Amravati-25-26'!$A$9:$D$190,3,0) -> 184166 | J35: =SUM(G35:I35) -> 184166 | K35: =+H35+G35-F35 -> 184166 | L35: =VLOOKUP(A35,'Profit Loss-Amravati-25-26'!$A$9:$F$190,5,0) -> 183672 | O35: =SUM(L35:M35) -> 183672 | P35: =+O35-J35 -> -494 | Q35: =VLOOKUP(A35,'Profit Loss-Amravati-25-26'!$A$9:$H$190,7,0) -> 183672 | T35: =+Q35+R35 -> 183672 | U35: =+T35-O35 -> 0 | V35: =VLOOKUP(A35,'Profit Loss-Amravati-25-26'!$A$9:$J$190,9,0) -> 183672 | Y35: =+V35+W35 -> 183672 | Z35: =+Y35-T35 -> 0 | AA35: =VLOOKUP(A35,'Profit Loss-Amravati-25-26'!$A$9:$L$192,11,0) -> 190161 | AD35: =+AA35+AB35-AC35 -> 190161 | AE35: =+AD35-Y35 -> 6489 | AF35: =VLOOKUP(A35,'Profit Loss-Amravati-25-26'!$A$9:$N$192,13,0) -> 190161 | AI35: =+AF35+AG35-AH35 -> 190161 | AJ35: =+AI35-AD35 -> 0 | AK35: =VLOOKUP(A35,'Profit Loss-Amravati-25-26'!$A$9:$P$192,15,0) -> 3927287.8 | AN35: =+AK35+AL35-AM35 -> 3927287.8 | AO35: =+AN35-AI35 -> 3737126.8 | AP35: =VLOOKUP(A35,'Profit Loss-Amravati-25-26'!$A$9:$R$192,17,0) -> 7846069 | AS35: =+AP35+AQ35-AR35 -> 7846069 | AT35: =+AS35-AN35 -> 3918781.2 | AU35: =VLOOKUP(A35,'Profit Loss-Amravati-25-26'!$A$9:$T$192,19,0) -> 7846069 | AX35: =+AU35+AV35-AW35 -> 7846069 | AY35: =+AX35-AS35 -> 0 | AZ35: =VLOOKUP(A35,'Profit Loss-Amravati-25-26'!$A$9:$V$192,21,0) -> 8387918.4 | BC35: =+AZ35+BA35-BB35 -> 8387918.4 | BD35: =+BC35-AX35 -> 541849.43
A36: COMMISSION/BROKERAGE | F36: =+B36+C36+D36 -> 0 | J36: =SUM(G36:I36) -> 0 | K36: =+H36+G36-F36 -> 0 | O36: =SUM(L36:M36) -> 0 | P36: =+O36-J36 -> 0 | T36: =SUM(Q36:R36) -> 0 | U36: =+T36-O36 -> 0 | Y36: =SUM(V36:W36) -> 0 | Z36: =+Y36-T36 -> 0 | AD36: =+AA36+AB36-AC36 -> 0 | AE36: =+AD36-Y36 -> 0 | AI36: =+AF36+AG36-AH36 -> 0 | AJ36: =+AI36-AD36 -> 0 | AK36: =VLOOKUP(A36,'Profit Loss-Amravati-25-26'!$A$9:$P$192,15,0) -> 70000 | AN36: =+AK36+AL36-AM36 -> 70000 | AO36: =+AN36-AI36 -> 70000 | AP36: =VLOOKUP(A36,'Profit Loss-Amravati-25-26'!$A$9:$R$192,17,0) -> 70000 | AS36: =+AP36+AQ36-AR36 -> 70000 | AT36: =+AS36-AN36 -> 0 | AU36: =VLOOKUP(A36,'Profit Loss-Amravati-25-26'!$A$9:$T$192,19,0) -> 70000 | AX36: =+AU36+AV36-AW36 -> 70000 | AY36: =+AX36-AS36 -> 0 | AZ36: =VLOOKUP(A36,'Profit Loss-Amravati-25-26'!$A$9:$V$192,21,0) -> 70000 | BC36: =+AZ36+BA36-BB36 -> 70000 | BD36: =+BC36-AX36 -> 0
A37: TOTAL EXPENSES RELATED TO SALES | B37: =SUM(B21:B36) -> 0 | C37: =SUM(C21:C36) -> 229146.3 | D37: =SUM(D21:D36) -> 0 | F37: =SUM(F21:F36) -> 229146.3 | G37: =SUM(G21:G36) -> 1159100.3 | H37: =SUM(H21:H36) -> 0 | J37: =SUM(J21:J36) -> 1159100.3 | K37: =SUM(K21:K36) -> 929954 | L37: =SUM(L21:L36) -> 2259807.1 | M37: =SUM(M21:M36) -> 12500 | O37: =SUM(O21:O36) -> 2272307.1 | P37: =SUM(P21:P36) -> 1113206.8 | Q37: =SUM(Q21:Q36) -> 4368755.9 | R37: =SUM(R21:R36) -> 12500 | T37: =SUM(T21:T36) -> 4381255.9 | U37: =SUM(U21:U36) -> 2108948.8 | V37: =SUM(V21:V36) -> 4985012.7 | W37: =SUM(W21:W36) -> 12500 | Y37: =SUM(Y21:Y36) -> 5297512.7 | Z37: =SUM(Z21:Z36) -> 916256.76 | AA37: =SUM(AA21:AA36) -> 6074350.4 | AB37: =SUM(AB21:AB36) -> 12500 | AD37: =SUM(AD21:AD36) -> 6086850.4 | AE37: =SUM(AE21:AE36) -> 789337.75 | AF37: =SUM(AF21:AF36) -> 7124421.2 | AG37: =SUM(AG21:AG36) -> 30500 | AI37: =SUM(AI21:AI36) -> 7154921.2 | AJ37: =SUM(AJ21:AJ36) -> 1068070.8 | AK37: =SUM(AK21:AK36) -> 12108829 | AL37: =SUM(AL21:AL36) -> 18500 | AN37: =SUM(AN21:AN36) -> 12127329 | AO37: =SUM(AO21:AO36) -> 4972407.7 | AP37: =SUM(AP21:AP36) -> 17905962 | AQ37: =SUM(AQ21:AQ36) -> 18500 | AS37: =SUM(AS21:AS36) -> 17924462 | AT37: =SUM(AT21:AT36) -> 5797133.1 | AU37: =SUM(AU21:AU36) -> 18837921 | AV37: =SUM(AV21:AV36) -> 18500 | AX37: =SUM(AX21:AX36) -> 18856421 | AY37: =SUM(AY21:AY36) -> 931959.15 | AZ37: =SUM(AZ21:AZ36) -> 20217957 | BA37: =SUM(BA21:BA36) -> 18500 | BC37: =SUM(BC21:BC36) -> 20236457 | BD37: =SUM(BD21:BD36) -> 1380036.1 | BE37: =+BC37-AX37-BD37 -> -1.8626451e-09
A38: NET SALES | B38: =B19-B37 -> 0 | C38: =C19-C37 -> 49362792 | D38: =D19-D37 -> 1501872 | F38: =F19-F37 -> 49362792 | G38: =G19-G37 -> 1.1147409e+08 | H38: =H19-H37 -> 2501098 | I38: =I19-I37 -> -2501098 | J38: =J19-J37 -> 1.1147409e+08 | K38: =K19-K37 -> 62111295 | L38: =L19-L37 -> 1.6749224e+08 | M38: =M19-M37 -> 5273679 | ... BD38: =BD19-BD37 -> 87954269 | BE38: =+BC38-AX38-BD38 -> 0
A39: OTHER OPERATING INCOME | L39: =VLOOKUP(A39,'Profit Loss-Amravati-25-26'!$A$9:$F$190,5,0) -> 0 | M39: =VLOOKUP(A39,'Profit Loss-Betul-25-26'!$A$9:$F$141,5,0) -> 0
A40: DEPB LICENCE SALE | G40: =VLOOKUP(A40,'Profit Loss-Amravati-25-26'!$A$9:$D$190,3,0) -> 316074 | J40: =SUM(G40:I40) -> 316074 | K40: =+H40+G40-F40 -> 316074 | L40: =VLOOKUP(A40,'Profit Loss-Amravati-25-26'!$A$9:$F$190,5,0) -> 316074 | O40: =SUM(L40:M40) -> 316074 | P40: =+O40-J40 -> 0 | Q40: =VLOOKUP(A40,'Profit Loss-Amravati-25-26'!$A$9:$H$190,7,0) -> 316074 | T40: =SUM(Q40:R40) -> 316074 | U40: =+T40-O40 -> 0 | V40: =VLOOKUP(A40,'Profit Loss-Amravati-25-26'!$A$9:$J$190,9,0) -> 316074 | Y40: =SUM(V40:W40) -> 316074 | Z40: =+Y40-T40 -> 0 | AA40: =VLOOKUP(A40,'Profit Loss-Amravati-25-26'!$A$9:$L$192,11,0) -> 6259301 | AD40: =+AA40+AB40-AC40 -> 6259301 | AE40: =+AD40-Y40 -> 5943227 | AF40: =VLOOKUP(A40,'Profit Loss-Amravati-25-26'!$A$9:$N$192,13,0) -> 6259301 | AI40: =+AF40+AG40-AH40 -> 6259301 | AJ40: =+AI40-AD40 -> 0 | AK40: =VLOOKUP(A40,'Profit Loss-Amravati-25-26'!$A$9:$P$192,15,0) -> 6259301 | AN40: =+AK40+AL40-AM40 -> 6259301 | AO40: =+AN40-AI40 -> 0 | AP40: =VLOOKUP(A40,'Profit Loss-Amravati-25-26'!$A$9:$R$192,17,0) -> 6259301 | AS40: =+AP40+AQ40-AR40 -> 6259301 | AT40: =+AS40-AN40 -> 0 | AU40: =VLOOKUP(A40,'Profit Loss-Amravati-25-26'!$A$9:$T$192,19,0) -> 7320935 | AX40: =+AU40+AV40-AW40 -> 7320935 | AY40: =+AX40-AS40 -> 1061634 | AZ40: =VLOOKUP(A40,'Profit Loss-Amravati-25-26'!$A$9:$V$192,21,0) -> 7320935 | BC40: =+AZ40+BA40-BB40 -> 7320935 | BD40: =+BC40-AX40 -> 0
A41: Rodtep Licence as per Receipt basis | G41: =VLOOKUP(A41,'Profit Loss-Amravati-25-26'!$A$9:$D$190,3,0) -> -316074 | J41: =SUM(G41:I41) -> -316074 | K41: =+H41+G41-F41 -> -316074 | L41: =VLOOKUP(A41,'Profit Loss-Amravati-25-26'!$A$9:$F$190,5,0) -> -316074 | O41: =SUM(L41:M41) -> -316074 | P41: =+O41-J41 -> 0 | Q41: =VLOOKUP(A41,'Profit Loss-Amravati-25-26'!$A$9:$H$190,7,0) -> -316074 | T41: =SUM(Q41:R41) -> -316074 | U41: =+T41-O41 -> 0 | V41: =VLOOKUP(A41,'Profit Loss-Amravati-25-26'!$A$9:$J$190,9,0) -> -316074 | Y41: =SUM(V41:W41) -> -316074 | Z41: =+Y41-T41 -> 0 | AA41: =VLOOKUP(A41,'Profit Loss-Amravati-25-26'!$A$9:$L$192,11,0) -> -6259301 | AD41: =+AA41+AB41-AC41 -> -6259301 | AE41: =+AD41-Y41 -> -5943227 | AF41: =VLOOKUP(A41,'Profit Loss-Amravati-25-26'!$A$9:$N$192,13,0) -> -6259301 | AI41: =+AF41+AG41-AH41 -> -6259301 | AJ41: =+AI41-AD41 -> 0 | AK41: =VLOOKUP(A41,'Profit Loss-Amravati-25-26'!$A$9:$P$192,15,0) -> -6259301 | AN41: =+AK41+AL41-AM41 -> -6259301 | AO41: =+AN41-AI41 -> 0 | AP41: =VLOOKUP(A41,'Profit Loss-Amravati-25-26'!$A$9:$R$192,17,0) -> -6259301 | AS41: =+AP41+AQ41-AR41 -> -6259301 | AT41: =+AS41-AN41 -> 0 | AU41: =VLOOKUP(A41,'Profit Loss-Amravati-25-26'!$A$9:$T$192,19,0) -> -7320935 | AX41: =+AU41+AV41-AW41 -> -7320935 | AY41: =+AX41-AS41 -> -1061634 | AZ41: =VLOOKUP(A41,'Profit Loss-Amravati-25-26'!$A$9:$V$192,21,0) -> -7320935 | BC41: =+AZ41+BA41-BB41 -> -7320935 | BD41: =+BC41-AX41 -> 0
...

Sheet Prepaid
C2: Total | D2: April,25 | E2: May,25 | F2: June,25 | G2: July,25
B3: SOFTWARE RENEWAL CHARGES PAID | C3: 3421 | D3: =+C3/12*11 -> 3135.9167 | E3: =+C3/12*10 -> 2850.8333 | F3: =+C3/12*9 -> 2565.75 | G3: =+C3/12*8 -> 2280.6667 | H3: =+C3/12*7 -> 1995.5833 | I3: =+C3/12*6 -> 1710.5 | J3: =+C3/12*5 -> 1425.4167 | K3: =+C3/12*4 -> 1140.3333 | L3: =+C3/12*3 -> 855.25 | M3: =+C3/12*2 -> 570.16667 | N3: =+C3/12*1 -> 285.08333
B4: POLLUTION CONTROL EXPENSES | C4: 25000 | D4: =+C4/12*11 -> 22916.667 | E4: =+C4/12*10 -> 20833.333 | F4: =+C4/12*9 -> 18750 | G4: =+C4/12*8 -> 16666.667 | H4: =+C4/12*7 -> 14583.333 | I4: =+C4/12*6 -> 12500 | J4: =+C4/12*5 -> 10416.667 | K4: =+C4/12*4 -> 8333.3333 | L4: =+C4/12*3 -> 6250 | M4: =+C4/12*2 -> 4166.6667 | N4: =+C4/12*1 -> 2083.3333
B5: REPAIRS & MAINTENANCE | C5: 355019 | D5: =+C5/12*11 -> 325434.08 | E5: =+C5/12*10 -> 295849.17 | F5: =+C5/12*9 -> 266264.25 | G5: =+C5/12*8 -> 236679.33 | H5: =+C5/12*7 -> 207094.42 | I5: =+C5/12*6 -> 177509.5 | J5: =+C5/12*5 -> 147924.58 | K5: =+C5/12*4 -> 118339.67 | L5: =+C5/12*3 -> 88754.75 | M5: =+C5/12*2 -> 59169.833 | N5: =+C5/12*1 -> 29584.917
B6: STAFF/WORKERS INSURANCE | C6: 243974 | D6: =+C6/12*11 -> 223642.83 | E6: =+C6/12*10 -> 203311.67 | F6: =+C6/12*9 -> 182980.5 | G6: =+C6/12*8 -> 162649.33 | H6: =+C6/12*7 -> 142318.17 | I6: =+C6/12*6 -> 121987 | J6: =+C6/12*5 -> 101655.83 | K6: =+C6/12*4 -> 81324.667 | L6: =+C6/12*3 -> 60993.5 | M6: =+C6/12*2 -> 40662.333 | N6: =+C6/12*1 -> 20331.167
B7: FACTORY LICENCE FEES | C7: 78756 | D7: =+C7/12*11 -> 72193 | E7: =+C7/12*10 -> 65630 | F7: =+C7/12*9 -> 59067 | G7: =+C7/12*8 -> 52504 | H7: =+C7/12*7 -> 45941 | I7: =+C7/12*6 -> 39378 | J7: =+C7/12*5 -> 32815 | K7: =+C7/12*4 -> 26252 | L7: =+C7/12*3 -> 19689 | M7: =+C7/12*2 -> 13126 | N7: =+C7/12*1 -> 6563
B8: INSURANCE (GENERAL) | C8: 272842 | D8: =+C8/12*11 -> 250105.17 | E8: =+C8/12*10 -> 227368.33 | F8: =+C8/12*9 -> 204631.5 | G8: =+C8/12*8 -> 181894.67 | H8: =+C8/12*7 -> 159157.83 | I8: =+C8/12*6 -> 136421 | J8: =+C8/12*5 -> 113684.17 | K8: =+C8/12*4 -> 90947.333 | L8: =+C8/12*3 -> 68210.5 | M8: =+C8/12*2 -> 45473.667 | N8: =+C8/12*1 -> 22736.833
B9: BANK GUARANTEE CHARGES | C9: 699 | D9: =+C9/12*11 -> 640.75 | E9: =+C9/12*10 -> 582.5 | F9: =+C9/12*9 -> 524.25 | G9: =+C9/12*8 -> 466 | H9: =+C9/12*7 -> 407.75 | I9: =+C9/12*6 -> 349.5 | J9: =+C9/12*5 -> 291.25 | K9: =+C9/12*4 -> 233 | L9: =+C9/12*3 -> 174.75 | M9: =+C9/12*2 -> 116.5 | N9: =+C9/12*1 -> 58.25
B10: TRAVELLING EXPENSES | C10: 7657 | D10: =+C10/12*11 -> 7018.9167 | E10: =+C10/12*10 -> 6380.8333 | F10: =+C10/12*9 -> 5742.75 | G10: =+C10/12*8 -> 5104.6667 | H10: =+C10/12*7 -> 4466.5833 | I10: =+C10/12*6 -> 3828.5 | J10: =+C10/12*5 -> 3190.4167 | K10: =+C10/12*4 -> 2552.3333 | L10: =+C10/12*3 -> 1914.25 | M10: =+C10/12*2 -> 1276.1667 | N10: =+C10/12*1 -> 638.08333
B11: FOREIGN TRAVELLING | C11: 116590 | D11: =+C11/12*11 -> 106874.17 | E11: =+C11/12*10 -> 97158.333 | F11: =+C11/12*9 -> 87442.5 | G11: =+C11/12*8 -> 77726.667 | H11: =+C11/12*7 -> 68010.833 | I11: =+C11/12*6 -> 58295 | J11: =+C11/12*5 -> 48579.167 | K11: =+C11/12*4 -> 38863.333 | L11: =+C11/12*3 -> 29147.5 | M11: =+C11/12*2 -> 19431.667 | N11: =+C11/12*1 -> 9715.8333
B12: LICENCE & LEGAL FEES | C12: -11432.8 | D12: =+C12/12*11 -> -10480.067 | E12: =+C12/12*10 -> -9527.3333 | F12: =+C12/12*9 -> -8574.6 | G12: =+C12/12*8 -> -7621.8667 | H12: =+C12/12*7 -> -6669.1333 | I12: =+C12/12*6 -> -5716.4 | J12: =+C12/12*5 -> -4763.6667 | K12: =+C12/12*4 -> -3810.9333 | L12: =+C12/12*3 -> -2858.2 | M12: =+C12/12*2 -> -1905.4667 | N12: =+C12/12*1 -> -952.73333
B13: Total | C13: =SUM(C3:C12) -> 1092525.2 | D13: =+C13/12*11 -> 1001481.4 | E13: =SUM(E3:E12) -> 910437.67 | F13: =SUM(F3:F12) -> 819393.9 | G13: =SUM(G3:G12) -> 728350.13 | J13: =SUM(J3:J12) -> 455218.83 | L13: =SUM(L3:L12) -> 273131.3 | N13: =SUM(N3:N12) -> 91043.767

Sheet Profit Loss-Amravati-25-26
A1: TECHNOCRAFT FASHIONS LIMITED-AMRAVATI DIVISION
A3: Profit & Loss for the period ended Feb, 2026
A6: PARTICULARS | B6: April, 25 | C6: Upto May, 25 | D6: For May, 25 | E6: Upto June, 25 | F6: For June, 25 | G6: Upto July, 25 | H6: For July, 25 | I6: Upto August, 25 | J6: For Aug, 25 | K6: Upto Sept, 25 | L6: For Sept, 25 | M6: Upto Oct, 25 | N6: For Oct, 25 | O6: Upto Nov, 25 | P6: For Nov, 25 | Q6: Upto Dec, 25 | R6: For Dec, 25 | S6: Upto Jan, 26 | T6: For Jan, 26 | U6: Upto Feb, 26 | V6: For Feb, 26
A7: INCOME
A8: SALES
A9: SALE EXPORT (GARMENT)) | C9: =VLOOKUP(A9,'May-A'!$B$10:$C$103,2,0) -> 17488529 | D9: =+C9-B9 -> 17488529 | E9: =VLOOKUP(A9,'June,25-A'!$B$10:$C$123,2,0) -> 17488529 | F9: =+E9-C9 -> 0 | G9: =VLOOKUP(A9,'July-A'!$B$10:$C$129,2,0) -> 28044991 | H9: =+G9-E9 -> 10556462 | I9: =VLOOKUP(A9,'TB-A-Aug'!$B$10:$C$132,2,0) -> 38932993 | J9: =+I9-G9 -> 10888002 | K9: =VLOOKUP(A9,'TFA-Sept,25'!$B$9:$C$136,2,0) -> 31936237 | L9: =+K9-I9 -> -6996756 | M9: =VLOOKUP(A9,'PL-TFA-Oct'!$B$9:$C$138,2,0) -> 58108673 | N9: =+M9-K9 -> 26172436 | O9: =VLOOKUP(A9,'TFA-Nov,25'!$B$10:$C$144,2,0) -> 73649850 | P9: =+O9-M9 -> 15541177 | Q9: =VLOOKUP(A9,'TB-TFL-A-Dec,25'!$B$10:$C$147,2,0) -> 84681620 | R9: =+Q9-O9 -> 11031770 | S9: =VLOOKUP(A9,'TB-TFL-A-Jan,26'!$B$9:$C$151,2,0) -> 84702821 | T9: =+S9-Q9 -> 21201 | U9: =VLOOKUP(A9,'TB-Feb,26-a'!$B$10:$C$153,2,0) -> 105750522 | V9: =+U9-S9 -> 21047701
A10: SALE EXPORT FABRIC | O10: =VLOOKUP(A10,'TFA-Nov,25'!$B$10:$C$144,2,0) -> 72061522 | P10: =+O10-M10 -> 72061522 | Q10: =VLOOKUP(A10,'TB-TFL-A-Dec,25'!$B$10:$C$147,2,0) -> 150117512 | R10: =+Q10-O10 -> 78055990 | S10: =VLOOKUP(A10,'TB-TFL-A-Jan,26'!$B$9:$C$151,2,0) -> 150117512 | T10: =+S10-Q10 -> 0 | U10: =VLOOKUP(A10,'TB-Feb,26-a'!$B$10:$C$153,2,0) -> 158852699 | V10: =+U10-S10 -> 8735187
A11: SALE EXPORT - FABRIC- (SAMPLE) | T11: =+S11-Q11 -> 0 | V11: =+U11-S11 -> 0
A12: SAMPLE DEVELOPMENT SERVICES | S12: =VLOOKUP(A12,'TB-TFL-A-Jan,26'!$B$9:$C$151,2,0)+180790 -> 646961 | T12: =+S12-Q12 -> 646961 | U12: =VLOOKUP(A12,'TB-Feb,26-a'!$B$10:$C$153,2,0) -> 646961 | V12: =+U12-S12 -> 0
A13: SALE LOCAL - MISCELLANEOUS ITEMS | B13: =VLOOKUP(A13,'TFL A-April,25'!$B$9:$C$95,2,0) -> 21860 | C13: =VLOOKUP(A13,'May-A'!$B$10:$C$103,2,0) -> 21860 | D13: =+C13-B13 -> 0 | E13: =VLOOKUP(A13,'June,25-A'!$B$10:$C$123,2,0) -> 21860 | F13: =+E13-C13 -> 0 | G13: =VLOOKUP(A13,'July-A'!$B$10:$C$129,2,0) -> 21860 | H13: =+G13-E13 -> 0 | I13: =VLOOKUP(A13,'TB-A-Aug'!$B$10:$C$132,2,0) -> 21860 | J13: =+I13-G13 -> 0 | K13: =VLOOKUP(A13,'TFA-Sept,25'!$B$9:$C$136,2,0) -> 21860 | L13: =+K13-I13 -> 0 | M13: =VLOOKUP(A13,'PL-TFA-Oct'!$B$9:$C$138,2,0) -> 21860 | N13: =+M13-K13 -> 0 | O13: =VLOOKUP(A13,'TFA-Nov,25'!$B$10:$C$144,2,0) -> 21860 | P13: =+O13-M13 -> 0 | Q13: =VLOOKUP(A13,'TB-TFL-A-Dec,25'!$B$10:$C$147,2,0) -> 21860 | R13: =+Q13-O13 -> 0 | S13: =VLOOKUP(A13,'TB-TFL-A-Jan,26'!$B$9:$C$151,2,0) -> 21860 | T13: =+S13-Q13 -> 0 | U13: =VLOOKUP(A13,'TB-Feb,26-a'!$B$10:$C$153,2,0) -> 21860 | V13: =+U13-S13 -> 0
A14: SALE LOCAL (GARMENT) | B14: =VLOOKUP(A14,'TFL A-April,25'!$B$9:$C$95,2,0) -> 47838869 | C14: =VLOOKUP(A14,'May-A'!$B$10:$C$103,2,0)-18103 -> 93255699 | D14: =+C14-B14 -> 45416830 | E14: =VLOOKUP(A14,'June,25-A'!$B$10:$C$123,2,0)-110927 -> 1.4859851e+08 | F14: =+E14-C14 -> 55342806 | G14: =VLOOKUP(A14,'July-A'!$B$10:$C$129,2,0) -> 2.2662015e+08 | H14: =+G14-E14 -> 78021644 | I14: =VLOOKUP(A14,'TB-A-Aug'!$B$10:$C$132,2,0) -> 2.7676371e+08 | J14: =+I14-G14 -> 50143556 | K14: =VLOOKUP(A14,'TFA-Sept,25'!$B$9:$C$136,2,0)-5839-20081-4468 -> 3.6038358e+08 | L14: =+K14-I14 -> 83619871 | M14: =VLOOKUP(A14,'PL-TFA-Oct'!$B$9:$C$138,2,0) -> 3.919506e+08 | N14: =+M14-K14 -> 31567025 | O14: =VLOOKUP(A14,'TFA-Nov,25'!$B$10:$C$144,2,0)-5229-4638 -> 4.3805378e+08 | P14: =+O14-M14 -> 46103174 | Q14: =VLOOKUP(A14,'TB-TFL-A-Dec,25'!$B$10:$C$147,2,0)-1839-20065-1760 -> 5.1824433e+08 | R14: =+Q14-O14 -> 80190553 | S14: =VLOOKUP(A14,'TB-TFL-A-Jan,26'!$B$9:$C$151,2,0)-(1311+6076+5650)-54021 -> 5.9101041e+08 | T14: =+S14-Q14 -> 72766078 | U14: =VLOOKUP(A14,'TB-Feb,26-a'!$B$10:$C$153,2,0)-6616-3651 -> 6.4868176e+08 | V14: =+U14-S14 -> 57671352
A15: SALE LOCAL | B15: =VLOOKUP(A15,'TFL A-April,25'!$B$9:$C$95,2,0) -> 26900 | C15: =VLOOKUP(A15,'May-A'!$B$10:$C$103,2,0) -> 162790 | D15: =+C15-B15 -> 135890 | E15: =VLOOKUP(A15,'June,25-A'!$B$10:$C$123,2,0) -> 162790 | F15: =+E15-C15 -> 0 | G15: =VLOOKUP(A15,'July-A'!$B$10:$C$129,2,0) -> 185950 | H15: =+G15-E15 -> 23160 | I15: =VLOOKUP(A15,'TB-A-Aug'!$B$10:$C$132,2,0) -> 205290 | J15: =+I15-G15 -> 19340 | K15: =VLOOKUP(A15,'TFA-Sept,25'!$B$9:$C$136,2,0) -> 439540 | L15: =+K15-I15 -> 234250 | M15: =VLOOKUP(A15,'PL-TFA-Oct'!$B$9:$C$138,2,0) -> 471500 | N15: =+M15-K15 -> 31960 | O15: =VLOOKUP(A15,'TFA-Nov,25'!$B$10:$C$144,2,0) -> 471500.01 | P15: =+O15-M15 -> 0.01 | Q15: =VLOOKUP(A15,'TB-TFL-A-Dec,25'!$B$10:$C$147,2,0) -> 471500.01 | R15: =+Q15-O15 -> 0 | S15: =VLOOKUP(A15,'TB-TFL-A-Jan,26'!$B$9:$C$151,2,0) -> 471500.01 | T15: =+S15-Q15 -> 0 | U15: =VLOOKUP(A15,'TB-Feb,26-a'!$B$10:$C$153,2,0) -> 471500.01 | V15: =+U15-S15 -> 0
A16: SALE TRADING - LOCAL - GARMENT | G16: =VLOOKUP(A16,'July-A'!$B$10:$C$129,2,0) -> 1961392 | H16: =+G16-E16 -> 1961392 | I16: =VLOOKUP(A16,'TB-A-Aug'!$B$10:$C$132,2,0) -> 2001211 | J16: =+I16-G16 -> 39819 | K16: =VLOOKUP(A16,'TFA-Sept,25'!$B$9:$C$136,2,0) -> 2001211 | L16: =+K16-I16 -> 0 | M16: =VLOOKUP(A16,'PL-TFA-Oct'!$B$9:$C$138,2,0) -> 2419148 | N16: =+M16-K16 -> 417937 | O16: =VLOOKUP(A16,'TFA-Nov,25'!$B$10:$C$144,2,0) -> 2419148 | P16: =+O16-M16 -> 0 | Q16: =VLOOKUP(A16,'TB-TFL-A-Dec,25'!$B$10:$C$147,2,0) -> 2821225 | R16: =+Q16-O16 -> 402077 | S16: =VLOOKUP(A16,'TB-TFL-A-Jan,26'!$B$9:$C$151,2,0) -> 3094230 | T16: =+S16-Q16 -> 273005 | U16: =VLOOKUP(A16,'TB-Feb,26-a'!$B$10:$C$153,2,0) -> 4971595 | V16: =+U16-S16 -> 1877365
A17: SALE TRADING - LOCAL - FABRIC | B17: =VLOOKUP(A17,'TFL A-April,25'!$B$9:$C$95,2,0) -> 1704310 | C17: =VLOOKUP(A17,'May-A'!$B$10:$C$103,2,0) -> 1704310 | D17: =+C17-B17 -> 0 | E17: =VLOOKUP(A17,'June,25-A'!$B$10:$C$123,2,0) -> 3480367 | F17: =+E17-C17 -> 1776057 | G17: =VLOOKUP(A17,'July-A'!$B$10:$C$129,2,0) -> 4008793 | H17: =+G17-E17 -> 528426 | I17: =VLOOKUP(A17,'TB-A-Aug'!$B$10:$C$132,2,0) -> 4930093 | J17: =+I17-G17 -> 921300 | K17: =VLOOKUP(A17,'TFA-Sept,25'!$B$9:$C$136,2,0) -> 5699323 | L17: =+K17-I17 -> 769230 | M17: =VLOOKUP(A17,'PL-TFA-Oct'!$B$9:$C$138,2,0) -> 5699323 | N17: =+M17-K17 -> 0 | O17: =VLOOKUP(A17,'TFA-Nov,25'!$B$10:$C$144,2,0) -> 6121968 | P17: =+O17-M17 -> 422645 | Q17: =VLOOKUP(A17,'TB-TFL-A-Dec,25'!$B$10:$C$147,2,0) -> 7995966 | R17: =+Q17-O17 -> 1873998 | S17: =VLOOKUP(A17,'TB-TFL-A-Jan,26'!$B$9:$C$151,2,0) -> 9757463 | T17: =+S17-Q17 -> 1761497 | U17: =VLOOKUP(A17,'TB-Feb,26-a'!$B$10:$C$153,2,0) -> 9760163 | V17: =+U17-S17 -> 2700
A18: GROSS SALES | B18: =SUM(B9:B17) -> 49591939 | C18: =SUM(C9:C17) -> 112633188 | D18: =SUM(D9:D17) -> 63041249 | E18: =SUM(E9:E17) -> 1.6975205e+08 | F18: =SUM(F9:F17) -> 57118863 | G18: =SUM(G9:G17) -> 2.6084314e+08 | H18: =SUM(H9:H17) -> 91091084 | I18: =SUM(I9:I17) -> 3.2285515e+08 | ... V18: =SUM(V9:V17) -> 89334305
A19: EXPENSES RELATED TO SALES
A20: PACKING EXPENSES | B20: =VLOOKUP(A20,'TFL A-April,25'!$B$9:$C$95,2,0) -> 370 | C20: =VLOOKUP(A20,'May-A'!$B$10:$C$103,2,0) -> 370 | D20: =+C20-B20 -> 0 | E20: =VLOOKUP(A20,'June,25-A'!$B$10:$C$123,2,0) -> 1170 | F20: =+E20-C20 -> 800 | G20: =VLOOKUP(A20,'July-A'!$B$10:$C$129,2,0) -> 1170 | H20: =+G20-E20 -> 0 | I20: =VLOOKUP(A20,'TB-A-Aug'!$B$10:$C$132,2,0) -> 1170 | J20: =+I20-G20 -> 0 | K20: =VLOOKUP(A20,'TFA-Sept,25'!$B$9:$C$136,2,0) -> 1170 | L20: =+K20-I20 -> 0 | M20: =VLOOKUP(A20,'PL-TFA-Oct'!$B$9:$C$138,2,0) -> 2270 | N20: =+M20-K20 -> 1100 | O20: =VLOOKUP(A20,'TFA-Nov,25'!$B$10:$C$144,2,0) -> 2470 | P20: =+O20-M20 -> 200 | Q20: =VLOOKUP(A20,'TB-TFL-A-Dec,25'!$B$10:$C$147,2,0) -> 3275 | R20: =+Q20-O20 -> 805 | S20: =VLOOKUP(A20,'TB-TFL-A-Jan,26'!$B$9:$C$151,2,0) -> 3275 | T20: =+S20-Q20 -> 0 | U20: =VLOOKUP(A20,'TB-Feb,26-a'!$B$10:$C$153,2,0) -> 3275 | V20: =+U20-S20 -> 0
A21: DELIVERY CHARGES ON SALES | B21: =VLOOKUP(A21,'TFL A-April,25'!$B$9:$C$95,2,0) -> 15803 | C21: =VLOOKUP(A21,'May-A'!$B$10:$C$103,2,0)+79714 -> 304524.24 | D21: =+C21-B21 -> 288721.24 | E21: =VLOOKUP(A21,'June,25-A'!$B$10:$C$123,2,0) -> 486121.24 | F21: =+E21-C21 -> 181597 | G21: =VLOOKUP(A21,'July-A'!$B$10:$C$129,2,0)+81644 -> 2209530.2 | H21: =+G21-E21 -> 1723409 | I21: =VLOOKUP(A21,'TB-A-Aug'!$B$10:$C$132,2,0)-57625 -> 2668553.2 | J21: =+I21-G21 -> 459022.98 | K21: =VLOOKUP(A21,'TFA-Sept,25'!$B$9:$C$136,2,0) -> 3139356.7 | L21: =+K21-I21 -> 470803.52 | M21: =VLOOKUP(A21,'PL-TFA-Oct'!$B$9:$C$138,2,0) -> 3321370.4 | N21: =+M21-K21 -> 182013.69 | O21: =VLOOKUP(A21,'TFA-Nov,25'!$B$10:$C$144,2,0) -> 3628852.1 | P21: =+O21-M21 -> 307481.71 | Q21: =VLOOKUP(A21,'TB-TFL-A-Dec,25'!$B$10:$C$147,2,0)+691760+308598 -> 4645461 | R21: =+Q21-O21 -> 1016608.9 | S21: =VLOOKUP(A21,'TB-TFL-A-Jan,26'!$B$9:$C$151,2,0)+176598+852906 -> 5114840.2 | T21: =+S21-Q21 -> 469379.11 | U21: =VLOOKUP(A21,'TB-Feb,26-a'!$B$10:$C$153,2,0)+1026514 -> 5627752.2 | V21: =+U21-S21 -> 512912
A22: DELIVERY CHARGES ON SALE -GARMENT | B22: =VLOOKUP(A22,'TFL A-April,25'!$B$9:$C$95,2,0) -> 212973.3 | C22: =VLOOKUP(A22,'May-A'!$B$10:$C$103,2,0) -> 382533.84 | D22: =+C22-B22 -> 169560.54 | E22: =VLOOKUP(A22,'June,25-A'!$B$10:$C$123,2,0)+617400 -> 1381133.8 | F22: =+E22-C22 -> 998600 | G22: =VLOOKUP(A22,'July-A'!$B$10:$C$129,2,0)+79715+669619 -> 1717980.4 | H22: =+G22-E22 -> 336846.6 | I22: =VLOOKUP(A22,'TB-A-Aug'!$B$10:$C$132,2,0)+58705+364483+57625 -> 1717980.4 | J22: =+I22-G22 -> 0 | K22: =VLOOKUP(A22,'TFA-Sept,25'!$B$9:$C$136,2,0)+500508 -> 2180159.7 | L22: =+K22-I22 -> 462179.23 | M22: =VLOOKUP(A22,'PL-TFA-Oct'!$B$9:$C$138,2,0)+'PL-TFA-Oct'!C69+411085 -> 2862982.8 | N22: =+M22-K22 -> 682823.14 | O22: =VLOOKUP(A22,'TFA-Nov,25'!$B$10:$C$144,2,0)+'TFA-Nov,25'!C71+631068 -> 3241559.8 | P22: =+O22-M22 -> 378577.02 | Q22: =VLOOKUP(A22,'TB-TFL-A-Dec,25'!$B$10:$C$147,2,0) -> 3456402.8 | R22: =+Q22-O22 -> 214843 | S22: =VLOOKUP(A22,'TB-TFL-A-Jan,26'!$B$9:$C$151,2,0) -> 3906763.1 | T22: =+S22-Q22 -> 450360.24 | U22: =VLOOKUP(A22,'TB-Feb,26-a'!$B$10:$C$153,2,0) -> 4065545.8 | V22: =+U22-S22 -> 158782.69
A23: CLEARING CHARGES ON EXPORT | D23: =+C23-B23 -> 0 | F23: =+E23-C23 -> 0 | H23: =+G23-E23 -> 0 | J23: =+I23-G23 -> 0 | L23: =+K23-I23 -> 0 | N23: =+M23-K23 -> 0 | P23: =+O23-M23 -> 0 | R23: =+Q23-O23 -> 0 | T23: =+S23-Q23 -> 0 | V23: =+U23-S23 -> 0
A24: DOCUMENTATION CHARGES | D24: =+C24-B24 -> 0 | F24: =+E24-C24 -> 0 | H24: =+G24-E24 -> 0 | J24: =+I24-G24 -> 0 | L24: =+K24-I24 -> 0 | N24: =+M24-K24 -> 0 | P24: =+O24-M24 -> 0 | R24: =+Q24-O24 -> 0 | T24: =+S24-Q24 -> 0 | V24: =+U24-S24 -> 0
A25: FREIGHT ON EXPORT
A26: FREIGHT ON EXPORT - (AIR) | D26: =+C26-B26 -> 0 | F26: =+E26-C26 -> 0 | H26: =+G26-E26 -> 0 | J26: =+I26-G26 -> 0 | L26: =+K26-I26 -> 0 | N26: =+M26-K26 -> 0 | P26: =+O26-M26 -> 0 | R26: =+Q26-O26 -> 0 | T26: =+S26-Q26 -> 0 | V26: =+U26-S26 -> 0
A27: TERMINAL HANDLING CHARGES | D27: =+C27-B27 -> 0 | F27: =+E27-C27 -> 0 | H27: =+G27-E27 -> 0 | J27: =+I27-G27 -> 0 | L27: =+K27-I27 -> 0 | N27: =+M27-K27 -> 0 | P27: =+O27-M27 -> 0 | R27: =+Q27-O27 -> 0 | T27: =+S27-Q27 -> 0 | V27: =+U27-S27 -> 0
A28: COOLIE & CARTAGE ON SALES | L28: =+K28-I28 -> 0 | N28: =+M28-K28 -> 0 | P28: =+O28-M28 -> 0 | R28: =+Q28-O28 -> 0 | T28: =+S28-Q28 -> 0 | V28: =+U28-S28 -> 0
A29: INSURANCE FOR EXPORT
A30: DELIVERY CHARGES ON SALE-FABRIC
A31: EXPORT EXPENSES | C31: =+SUM('May-A'!C46:C50)-'May-A'!C48 -> 207710.22 | D31: =+C31-B31 -> 207710.22 | E31: 207710 | F31: =+E31-C31 -> -0.22 | G31: =256403.22 -> 256403.22 | H31: =+G31-E31 -> 48693.22 | I31: =268673.22+144964 -> 413637.22 | J31: =+I31-G31 -> 157234 | K31: =VLOOKUP(A31,'TFA-Sept,25'!$B$9:$C$136,2,0)+340147+132287 -> 474954 | L31: =+K31-I31 -> 61316.78 | M31: =2520+526552-63882+61611+132287 -> 659088 | N31: =+M31-K31 -> 184134 | O31: =1019685.22+130425 -> 1150110.2 | P31: =+O31-M31 -> 491022.22 | Q31: =1501885.22+52450+241870 -> 1796205.2 | R31: =+Q31-O31 -> 646095 | S31: =1808425.02 -> 1808425 | T31: =+S31-Q31 -> 12219.8 | U31: 1974917.5 | V31: =+U31-S31 -> 166492.44
A32: DETENTION CHARGES ON EXPORT | D32: =+C32-B32 -> 0 | F32: =+E32-C32 -> 0 | H32: =+G32-E32 -> 0 | J32: =+I32-G32 -> 0 | L32: =+K32-I32 -> 0 | N32: =+M32-K32 -> 0 | P32: =+O32-M32 -> 0 | R32: =+Q32-O32 -> 0 | T32: =+S32-Q32 -> 0 | V32: =+U32-S32 -> 0
A33: MARKETING DEVELOPMENT ASSISTANCE | K33: =VLOOKUP(A33,'TFA-Sept,25'!$B$9:$C$136,2,0) -> 88549 | L33: =+K33-I33 -> 88549 | M33: =VLOOKUP(A33,'PL-TFA-Oct'!$B$9:$C$138,2,0) -> 88549 | N33: =+M33-K33 -> 0 | O33: =VLOOKUP(A33,'TFA-Nov,25'!$B$10:$C$144,2,0) -> 88549 | P33: =+O33-M33 -> 0 | Q33: =VLOOKUP(A33,'TB-TFL-A-Dec,25'!$B$10:$C$147,2,0) -> 88549 | R33: =+Q33-O33 -> 0 | S33: =VLOOKUP(A33,'TB-TFL-A-Jan,26'!$B$9:$C$151,2,0) -> 88549 | T33: =+S33-Q33 -> 0 | U33: =VLOOKUP(A33,'TB-Feb,26-a'!$B$10:$C$153,2,0) -> 88549 | V33: =+U33-S33 -> 0
A34: BUSINESS SUPPORT SERVICES | C34: 184166 | D34: =+C34-B34 -> 184166 | E34: 183672 | F34: =+E34-C34 -> -494 | G34: 183672 | H34: =+G34-E34 -> 0 | I34: 183672 | J34: =+I34-G34 -> 0 | K34: 190161 | L34: =+K34-I34 -> 6489 | M34: 190161 | N34: =+M34-K34 -> 0 | O34: =238351+3688936.7508 -> 3927287.8 | P34: =+O34-M34 -> 3737126.8 | Q34: =241278+7604791 -> 7846069 | R34: =+Q34-O34 -> 3918781.2 | S34: =241278+7604791 -> 7846069 | T34: =+S34-Q34 -> 0 | U34: =VLOOKUP(A34,'TB-Feb,26-a'!$B$10:$C$153,2,0)+2543939+92175 -> 8387918.4 | V34: =+U34-S34 -> 541849.43
A35: COMMISSION/BROKERAGE | O35: =VLOOKUP(A35,'TFA-Nov,25'!$B$10:$C$144,2,0) -> 70000 | P35: =+O35-M35 -> 70000 | Q35: =VLOOKUP(A35,'TB-TFL-A-Dec,25'!$B$10:$C$147,2,0) -> 70000 | R35: =+Q35-O35 -> 0 | S35: =VLOOKUP(A35,'TB-TFL-A-Jan,26'!$B$9:$C$151,2,0) -> 70000 | T35: =+S35-Q35 -> 0 | U35: =VLOOKUP(A35,'TB-Feb,26-a'!$B$10:$C$153,2,0) -> 70000 | V35: =+U35-S35 -> 0
A36: TOTAL EXPENSES RELATED TO SALES | B36: =SUM(B20:B34) -> 229146.3 | C36: =SUM(C20:C34) -> 1079304.3 | D36: =SUM(D20:D34) -> 850158 | E36: =SUM(E20:E34) -> 2259807.1 | F36: =SUM(F20:F34) -> 1180502.8 | G36: =SUM(G20:G34) -> 4368755.9 | H36: =SUM(H20:H34) -> 2108948.8 | I36: =SUM(I20:I34) -> 4985012.9 | ... N36: =SUM(N20:N34) -> 1050070.8 | O36: =SUM(O20:O35) -> 12108829 | P36: =SUM(P20:P35) -> 4984407.7 | Q36: =SUM(Q20:Q35) -> 17905962 | R36: =SUM(R20:R35) -> 5797133.1 | S36: =SUM(S20:S35) -> 18837921 | T36: =SUM(T20:T35) -> 931959.15 | U36: =SUM(U20:U35) -> 20217958 | V36: =SUM(V20:V35) -> 1380036.6
A37: NET SALES | B37: =B18-B36 -> 49362792 | C37: =C18-C36 -> 1.1155388e+08 | D37: =D18-D36 -> 62191091 | E37: =E18-E36 -> 1.6749224e+08 | F37: =F18-F36 -> 55938361 | G37: =G18-G36 -> 2.5647438e+08 | H37: =H18-H36 -> 88982135 | I37: =I18-I36 -> 3.1787014e+08 | ... V37: =V18-V36 -> 87954268
A38: OTHER OPERATING INCOME
A39: DUTY DRAWBACK RECEIVED | C39: 517983 | D39: =+C39-B39 -> 517983 | E39: =VLOOKUP(A39,'June,25-A'!$B$10:$C$123,2,0)+2190 -> 517983 | F39: =+E39-D39 -> 0 | G39: =VLOOKUP(A39,'July-A'!$B$10:$C$129,2,0)+45560 -> 836371 | H39: =+G39-E39 -> 318388 | I39: =VLOOKUP(A39,'TB-A-Aug'!$B$10:$C$132,2,0)+329601 -> 1163782 | J39: =+I39-G39 -> 327411 | K39: =VLOOKUP(A39,'TFA-Sept,25'!$B$9:$C$136,2,0)+372686 -> 1248612 | L39: =+K39-I39 -> 84830 | M39: =VLOOKUP(A39,'PL-TFA-Oct'!$B$9:$C$138,2,0)+790611 -> 1751367 | N39: =+M39-K39 -> 502755 | O39: =VLOOKUP(A39,'TFA-Nov,25'!$B$10:$C$144,2,0)+1948603 -> 3861478 | P39: =+O39-M39 -> 2110111 | Q39: =VLOOKUP(A39,'TB-TFL-A-Dec,25'!$B$10:$C$147,2,0)-427543+3559740 -> 6018309 | R39: =+Q39-O39 -> 2156831 | S39: =VLOOKUP(A39,'TB-TFL-A-Jan,26'!$B$9:$C$151,2,0)+875342-209645 -> 6018905 | T39: =+S39-Q39 -> 596 | U39: =VLOOKUP(A39,'TB-Feb,26-a'!$B$10:$C$153,2,0)+1301521 -> 6655556 | V39: =+U39-S39 -> 636651
A40: DEPB LICENCE SALE | C40: =VLOOKUP(A40,'May-A'!$B$10:$C$103,2,0) -> 316074 | D40: =+C40-B40 -> 316074 | E40: =VLOOKUP(A40,'June,25-A'!$B$10:$C$123,2,0) -> 316074 | F40: =+E40-C40 -> 0 | G40: =VLOOKUP(A40,'July-A'!$B$10:$C$129,2,0) -> 316074 | H40: =+G40-E40 -> 0 | I40: =VLOOKUP(A40,'TB-A-Aug'!$B$10:$C$132,2,0) -> 316074 | J40: =+I40-G40 -> 0 | K40: =VLOOKUP(A40,'TFA-Sept,25'!$B$9:$C$136,2,0) -> 6259301 | L40: =+K40-I40 -> 5943227 | M40: =VLOOKUP(A40,'PL-TFA-Oct'!$B$9:$C$138,2,0) -> 6259301 | N40: =+M40-K40 -> 0 | O40: =VLOOKUP(A40,'TFA-Nov,25'!$B$10:$C$144,2,0) -> 6259301 | P40: =+O40-M40 -> 0 | Q40: =VLOOKUP(A40,'TB-TFL-A-Dec,25'!$B$10:$C$147,2,0) -> 6259301 | R40: =+Q40-O40 -> 0 | S40: =VLOOKUP(A40,'TB-TFL-A-Jan,26'!$B$9:$C$151,2,0) -> 7320935 | T40: =+S40-Q40 -> 1061634 | U40: =VLOOKUP(A40,'TB-Feb,26-a'!$B$10:$C$153,2,0) -> 7320935 | V40: =+U40-S40 -> 0
A41: Rodtep Licence as per Receipt basis | C41: =-C40 -> -316074 | D41: =+C41-B41 -> -316074 | E41: =-E40 -> -316074 | F41: =+E41-C41 -> 0 | G41: =-G40 -> -316074 | H41: =+G41-E41 -> 0 | I41: =-I40 -> -316074 | J41: =+I41-G41 -> 0 | K41: =-K40 -> -6259301 | L41: =+K41-I41 -> -5943227 | M41: =-M40 -> -6259301 | N41: =+M41-K41 -> 0 | O41: =-O40 -> -6259301 | P41: =+O41-M41 -> 0 | Q41: =-Q40 -> -6259301 | R41: =+Q41-O41 -> 0 | S41: =-S40 -> -7320935 | T41: =+S41-Q41 -> -1061634 | U41: =-U40 -> -7320935 | V41: =+U41-S41 -> 0
A42: Rodtep Licence as per Accrual basis | C42: 859887 | D42: =+C42-B42 -> 859887 | E42: 859887 | F42: =+E42-C42 -> 0 | G42: 1347177 | H42: =+G42-E42 -> 487290 | I42: 1755145 | J42: =+I42-G42 -> 407968 | K42: 1849897 | L42: =+K42-I42 -> 94752 | M42: 2694207 | N42: =+M42-K42 -> 844310 | O42: 5431594 | P42: =+O42-M42 -> 2737387 | Q42: =4042289+4093906 -> 8136195 | R42: =+Q42-O42 -> 2704601 | S42: 8137208 | T42: =+S42-Q42 -> 1013 | U42: 8978541 | V42: =+U42-S42 -> 841333
A43: SALE SCRAP | B43: =VLOOKUP(A43,'TFL A-April,25'!$B$9:$C$95,2,0) -> 21100 | C43: =VLOOKUP(A43,'May-A'!$B$10:$C$103,2,0) -> 75856 | D43: =+C43-B43 -> 54756 | E43: =VLOOKUP(A43,'June,25-A'!$B$10:$C$123,2,0) -> 122094 | F43: =+E43-C43 -> 46238 | G43: =VLOOKUP(A43,'July-A'!$B$10:$C$129,2,0) -> 155784 | H43: =+G43-E43 -> 33690 | I43: =VLOOKUP(A43,'TB-A-Aug'!$B$10:$C$132,2,0) -> 510434 | J43: =+I43-G43 -> 354650 | K43: =VLOOKUP(A43,'TFA-Sept,25'!$B$9:$C$136,2,0) -> 533514 | L43: =+K43-I43 -> 23080 | M43: =VLOOKUP(A43,'PL-TFA-Oct'!$B$9:$C$138,2,0) -> 533514 | N43: =+M43-K43 -> 0 | O43: =VLOOKUP(A43,'TFA-Nov,25'!$B$10:$C$144,2,0) -> 575364 | P43: =+O43-M43 -> 41850 | Q43: =VLOOKUP(A43,'TB-TFL-A-Dec,25'!$B$10:$C$147,2,0) -> 627514 | R43: =+Q43-O43 -> 52150 | S43: =VLOOKUP(A43,'TB-TFL-A-Jan,26'!$B$9:$C$151,2,0) -> 644564 | T43: =+S43-Q43 -> 17050 | U43: =VLOOKUP(A43,'TB-Feb,26-a'!$B$10:$C$153,2,0) -> 682214 | V43: =+U43-S43 -> 37650
...

Sheet Profit Loss-Betul-25-26
A1: TECHNOCRAFT FASHIONS LIMITED-BETUL
A3: Profit & Loss for the period ended Feb, 2026
